Workbook

Sheet Analysis
E7: Average of TotalWater_m3_tonCu | G7: Ref_Water2
E8: Mine_type | F8: Deposit | G8: Lutter et al. (2025) | H8: Northey et al. (2013) | I8: Islam et al. (2020) | J8: Peña et al. (2014) | K8: Gunson (2013) | L8: Mudd (2008) | M8: Dai et al. (2018) | N8: Grand Total
E9: Combined | F9: Andina | H9: 99.4 | N9: 99.4
F10: Boddington | G10: 750 | N10: 750
F11: Cadia East | G11: 148 | N11: 148
F12: Cadia-Ridgeway | H12: 49 | N12: 49
F13: Dexing Complex | G13: 162 | N13: 162
F14: El Soldado | H14: 48.2 | N14: 48.2
F15: El Teniente | G15: 151 | N15: 151
F16: Grasberg | G16: 163 | N16: 163
F17: Jabal Sayid | G17: 90 | N17: 90
F18: Kamoto | G18: 49 | N18: 49
F19: Kansanshi | G19: 197 | N19: 197
F20: Kennecott | G20: 123 | N20: 123
F21: Kola Division | G21: 321 | N21: 321
F22: Malanjkhand | G22: 71 | N22: 71
F23: Mission | G23: 379 | N23: 379
F24: Mt Isa Copper | G24: 61 | N24: 61
F25: Northparkes | H25: 74 | N25: 74
F26: Ok Tedi | G26: 119 | N26: 119
F27: Polar Division | G27: 74 | N27: 74
F28: Salvador | H28: 321.3 | N28: 321.3
F29: Telfer | G29: 1181 | H29: 161.1 | N29: 671.05
F30: Zhezkazgan Complex | G30: 142 | N30: 142
F31: (blank) | K31: 125.76443 | L31: 131.66667 | N31: 127.37413
E32: Open Pit | F32: Aitik | G32: 267 | N32: 267
F33: Alumbrera | H33: 91.3 | N33: 91.3
F34: Bagdad | G34: 152 | N34: 152
F35: Batu Hijau | G35: 129 | N35: 129
F36: Cerro Verde | G36: 118 | N36: 118
F37: Chuquicamata | G37: 163 | N37: 163
F38: Cobre Panama | G38: 826 | N38: 826
F39: Codelco Norte | H39: 53.3 | J39: 51.1 | N39: 51.833333
F40: Collahuasi | H40: 31.9 | N40: 31.9
F41: Erdenet | G41: 192 | N41: 192
F42: Ernest Henry | H42: 42.3 | N42: 42.3
F43: Escondida | G43: 85 | H43: 52.5 | J43: 24.8 | N43: 46.775
F44: Highland Valley | G44: 161 | N44: 161
F45: Kennecott Utah | H45: 9.8 | N45: 9.8
F46: Kidd Creek | H46: 76.7 | N46: 76.7
...

Sheet TD_Table1
F7: Values
E8: Mineral | F8: Average of Grade ore Cu% | G8: Average of TotalWater_m3_tonCu | H8: Average of m3_perTonOre
E9: Cobalt | F9: 0.00026 | G9: 307.69231 | H9: 0.08
E10: Copper | F10: 0.010220614 | G10: 149.98997 | H10: 1.1958362
E11: Nickel | F11: 0.011809813 | G11: 152.73995 | H11: 1.5078
E12: Grand Total | F12: 0.010184211 | G12: 151.66029 | H12: 1.1971697

Sheet Data
A1: Order | B1: Mineral | C1: Country | D1: Deposit | E1: Resource_type | F1: Mine_type | G1: Products | H1: Grade ore Cu% | I1: Ref_grade | J1: Freshwater | K1: Unit num | L1: Unit den | M1: Detail | N1: Water type | O1: Ref_Water | P1: Ref_Water2 | Q1: TotalWater_m3_tonCu | R1: m3_perTonOre
A2: 1 | B2: Copper | C2: =+Northey2013!A3 -> Australia | D2: =+Northey2013!B3 -> Cadia-Ridgeway | E2: =+Northey2013!D3 -> Porphyry | F2: =VLOOKUP(+Northey2013!F3,Northey2013!$A$39:$B$41,2,0) -> Combined | G2: =+Northey2013!E3 -> Au–Cu | H2: =+Northey2013!I3/100 -> 0.0033 | I2: 1 | J2: 49 | K2: kL | L2: t Cu | N2: water is used in various ways such as to control moisture content in slopes, dust suppression and to cool drilling and hauling equipment. Water is required in the beneficiation stage to ensure optimal grinding of ore, to allow transfer of concentrate slurry between unit processes and for flotation processes. Additionally, water may be used to cool heavy machinery and furnaces. A modest amount of water is also required for potable uses. | O2: 1 | P2: =+VLOOKUP(O2,References!$A$2:$F$29,2,0) -> Northey et al. (2013) | Q2: =+VLOOKUP(K2&L2,Unit_Normalization!$A$2:$D$24,4,0)*J2 -> 49 | R2: =+Table1[[#This Row],[TotalWater_m3_tonCu]]*Table1[[#This Row],[Grade ore Cu%]] -> 0.1617
A3: 2 | B3: Copper | C3: =+Northey2013!A4 -> Australia | D3: =+Northey2013!B4 -> Ernest Henry | E3: =+Northey2013!D4 -> IOCG | F3: =VLOOKUP(+Northey2013!F4,Northey2013!$A$39:$B$41,2,0) -> Open Pit | G3: =+Northey2013!E4 -> Cu–Au | H3: =+Northey2013!I4/100 -> 0.0098 | I3: 1 | J3: 42.3 | K3: kL | L3: t Cu | N3: water is used in various ways such as to control moisture content in slopes, dust suppression and to cool drilling and hauling equipment. Water is required in the beneficiation stage to ensure optimal grinding of ore, to allow transfer of concentrate slurry between unit processes and for flotation processes. Additionally, water may be used to cool heavy machinery and furnaces. A modest amount of water is also required for potable uses. | O3: 1 | P3: =+VLOOKUP(O3,References!$A$2:$F$29,2,0) -> Northey et al. (2013) | Q3: =+VLOOKUP(K3&L3,Unit_Normalization!$A$2:$D$24,4,0)*J3 -> 42.3 | R3: =+Table1[[#This Row],[TotalWater_m3_tonCu]]*Table1[[#This Row],[Grade ore Cu%]] -> 0.41454
A4: 3 | B4: Copper | C4: =+Northey2013!A5 -> Australia | D4: =+Northey2013!B5 -> Golden Grove | E4: =+Northey2013!D5 -> VMS | F4: =VLOOKUP(+Northey2013!F5,Northey2013!$A$39:$B$41,2,0) -> Underground | G4: =+Northey2013!E5 -> Ag–Pb–Zn–Cu | H4: =+Northey2013!I5/100 -> 0.0185 | I4: 1 | J4: 33 | K4: kL | L4: t Cu | N4: water is used in various ways such as to control moisture content in slopes, dust suppression and to cool drilling and hauling equipment. Water is required in the beneficiation stage to ensure optimal grinding of ore, to allow transfer of concentrate slurry between unit processes and for flotation processes. Additionally, water may be used to cool heavy machinery and furnaces. A modest amount of water is also required for potable uses. | O4: 1 | P4: =+VLOOKUP(O4,References!$A$2:$F$29,2,0) -> Northey et al. (2013) | Q4: =+VLOOKUP(K4&L4,Unit_Normalization!$A$2:$D$24,4,0)*J4 -> 33 | R4: =+Table1[[#This Row],[TotalWater_m3_tonCu]]*Table1[[#This Row],[Grade ore Cu%]] -> 0.6105
A5: 4 | B5: Copper | C5: =+Northey2013!A6 -> Australia | D5: =+Northey2013!B6 -> Mount Isa | E5: =+Northey2013!D6 -> SedEx | F5: =VLOOKUP(+Northey2013!F6,Northey2013!$A$39:$B$41,2,0) -> Underground | G5: =+Northey2013!E6 -> Cu | H5: =+Northey2013!I6/100 -> 0.0321 | I5: 1 | J5: 19.5 | K5: kL | L5: t Cu | N5: water is used in various ways such as to control moisture content in slopes, dust suppression and to cool drilling and hauling equipment. Water is required in the beneficiation stage to ensure optimal grinding of ore, to allow transfer of concentrate slurry between unit processes and for flotation processes. Additionally, water may be used to cool heavy machinery and furnaces. A modest amount of water is also required for potable uses. | O5: 1 | P5: =+VLOOKUP(O5,References!$A$2:$F$29,2,0) -> Northey et al. (2013) | Q5: =+VLOOKUP(K5&L5,Unit_Normalization!$A$2:$D$24,4,0)*J5 -> 19.5 | R5: =+Table1[[#This Row],[TotalWater_m3_tonCu]]*Table1[[#This Row],[Grade ore Cu%]] -> 0.62595
A6: 5 | B6: Copper | C6: =+Northey2013!A7 -> Australia | D6: =+Northey2013!B7 -> Northparkes | E6: =+Northey2013!D7 -> Porphyry | F6: =VLOOKUP(+Northey2013!F7,Northey2013!$A$39:$B$41,2,0) -> Combined | G6: =+Northey2013!E7 -> Cu–Au | H6: =+Northey2013!I7/100 -> 0.0078 | I6: 1 | J6: 74 | K6: kL | L6: t Cu | N6: water is used in various ways such as to control moisture content in slopes, dust suppression and to cool drilling and hauling equipment. Water is required in the beneficiation stage to ensure optimal grinding of ore, to allow transfer of concentrate slurry between unit processes and for flotation processes. Additionally, water may be used to cool heavy machinery and furnaces. A modest amount of water is also required for potable uses. | O6: 1 | P6: =+VLOOKUP(O6,References!$A$2:$F$29,2,0) -> Northey et al. (2013) | Q6: =+VLOOKUP(K6&L6,Unit_Normalization!$A$2:$D$24,4,0)*J6 -> 74 | R6: =+Table1[[#This Row],[TotalWater_m3_tonCu]]*Table1[[#This Row],[Grade ore Cu%]] -> 0.5772
A7: 6 | B7: Copper | C7: =+Northey2013!A8 -> Australia | D7: =+Northey2013!B8 -> Olympic Dam | E7: =+Northey2013!D8 -> IOCG | F7: =VLOOKUP(+Northey2013!F8,Northey2013!$A$39:$B$41,2,0) -> Underground | G7: =+Northey2013!E8 -> Cu–Au–Ag–U | H7: =+Northey2013!I8/100 -> 0.0246 | I7: 1 | J7: 46.6 | K7: kL | L7: t Cu | N7: water is used in various ways such as to control moisture content in slopes, dust suppression and to cool drilling and hauling equipment. Water is required in the beneficiation stage to ensure optimal grinding of ore, to allow transfer of concentrate slurry between unit processes and for flotation processes. Additionally, water may be used to cool heavy machinery and furnaces. A modest amount of water is also required for potable uses. | O7: 1 | P7: =+VLOOKUP(O7,References!$A$2:$F$29,2,0) -> Northey et al. (2013) | Q7: =+VLOOKUP(K7&L7,Unit_Normalization!$A$2:$D$24,4,0)*J7 -> 46.6 | R7: =+Table1[[#This Row],[TotalWater_m3_tonCu]]*Table1[[#This Row],[Grade ore Cu%]] -> 1.14636
A8: 7 | B8: Copper | C8: =+Northey2013!A9 -> Australia | D8: =+Northey2013!B9 -> Prominent Hill | E8: =+Northey2013!D9 -> IOCG | F8: =VLOOKUP(+Northey2013!F9,Northey2013!$A$39:$B$41,2,0) -> Open Pit | G8: =+Northey2013!E9 -> Cu–Au–Ag | H8: =+Northey2013!I9/100 -> 0.0154 | I8: 1 | J8: 39.8 | K8: kL | L8: t Cu | N8: water is used in various ways such as to control moisture content in slopes, dust suppression and to cool drilling and hauling equipment. Water is required in the beneficiation stage to ensure optimal grinding of ore, to allow transfer of concentrate slurry between unit processes and for flotation processes. Additionally, water may be used to cool heavy machinery and furnaces. A modest amount of water is also required for potable uses. | O8: 1 | P8: =+VLOOKUP(O8,References!$A$2:$F$29,2,0) -> Northey et al. (2013) | Q8: =+VLOOKUP(K8&L8,Unit_Normalization!$A$2:$D$24,4,0)*J8 -> 39.8 | R8: =+Table1[[#This Row],[TotalWater_m3_tonCu]]*Table1[[#This Row],[Grade ore Cu%]] -> 0.61292
A9: 8 | B9: Copper | C9: =+Northey2013!A10 -> Australia | D9: =+Northey2013!B10 -> Rosebery | E9: =+Northey2013!D10 -> VMS | F9: =VLOOKUP(+Northey2013!F10,Northey2013!$A$39:$B$41,2,0) -> Underground | G9: =+Northey2013!E10 -> Ag–Pb–Zn–Cu–Au | H9: =+Northey2013!I10/100 -> 0.0036 | I9: 1 | J9: 1046.9 | K9: kL | L9: t Cu | N9: water is used in various ways such as to control moisture content in slopes, dust suppression and to cool drilling and hauling equipment. Water is required in the beneficiation stage to ensure optimal grinding of ore, to allow transfer of concentrate slurry between unit processes and for flotation processes. Additionally, water may be used to cool heavy machinery and furnaces. A modest amount of water is also required for potable uses. | O9: 1 | P9: =+VLOOKUP(O9,References!$A$2:$F$29,2,0) -> Northey et al. (2013) | Q9: =+VLOOKUP(K9&L9,Unit_Normalization!$A$2:$D$24,4,0)*J9 -> 1046.9 | R9: =+Table1[[#This Row],[TotalWater_m3_tonCu]]*Table1[[#This Row],[Grade ore Cu%]] -> 3.76884
A10: 9 | B10: Copper | C10: =+Northey2013!A11 -> Australia | D10: =+Northey2013!B11 -> Telfer | E10: =+Northey2013!D11 -> OGC | F10: =VLOOKUP(+Northey2013!F11,Northey2013!$A$39:$B$41,2,0) -> Combined | G10: =+Northey2013!E11 -> Au–Cu | H10: =+Northey2013!I11/100 -> 0.0024 | I10: 1 | J10: 161.1 | K10: kL | L10: t Cu | N10: water is used in various ways such as to control moisture content in slopes, dust suppression and to cool drilling and hauling equipment. Water is required in the beneficiation stage to ensure optimal grinding of ore, to allow transfer of concentrate slurry between unit processes and for flotation processes. Additionally, water may be used to cool heavy machinery and furnaces. A modest amount of water is also required for potable uses. | O10: 1 | P10: =+VLOOKUP(O10,References!$A$2:$F$29,2,0) -> Northey et al. (2013) | Q10: =+VLOOKUP(K10&L10,Unit_Normalization!$A$2:$D$24,4,0)*J10 -> 161.1 | R10: =+Table1[[#This Row],[TotalWater_m3_tonCu]]*Table1[[#This Row],[Grade ore Cu%]] -> 0.38664
A11: 10 | B11: Copper | C11: =+Northey2013!A12 -> Argentina | D11: =+Northey2013!B12 -> Alumbrera | E11: =+Northey2013!D12 -> Porphyry | F11: =VLOOKUP(+Northey2013!F12,Northey2013!$A$39:$B$41,2,0) -> Open Pit | G11: =+Northey2013!E12 -> Cu–Au | H11: =+Northey2013!I12/100 -> 0.0055 | I11: 1 | J11: 91.3 | K11: kL | L11: t Cu | N11: water is used in various ways such as to control moisture content in slopes, dust suppression and to cool drilling and hauling equipment. Water is required in the beneficiation stage to ensure optimal grinding of ore, to allow transfer of concentrate slurry between unit processes and for flotation processes. Additionally, water may be used to cool heavy machinery and furnaces. A modest amount of water is also required for potable uses. | O11: 1 | P11: =+VLOOKUP(O11,References!$A$2:$F$29,2,0) -> Northey et al. (2013) | Q11: =+VLOOKUP(K11&L11,Unit_Normalization!$A$2:$D$24,4,0)*J11 -> 91.3 | R11: =+Table1[[#This Row],[TotalWater_m3_tonCu]]*Table1[[#This Row],[Grade ore Cu%]] -> 0.50215
A12: 11 | B12: Copper | C12: =+Northey2013!A13 -> Canada | D12: =+Northey2013!B13 -> Highland Valley | E12: =+Northey2013!D13 -> Porphyry | F12: =VLOOKUP(+Northey2013!F13,Northey2013!$A$39:$B$41,2,0) -> Underground | G12: =+Northey2013!E13 -> Cu–Mo | H12: =+Northey2013!I13/100 -> 0.004 | I12: 1 | J12: 135.4 | K12: kL | L12: t Cu | N12: water is used in various ways such as to control moisture content in slopes, dust suppression and to cool drilling and hauling equipment. Water is required in the beneficiation stage to ensure optimal grinding of ore, to allow transfer of concentrate slurry between unit processes and for flotation processes. Additionally, water may be used to cool heavy machinery and furnaces. A modest amount of water is also required for potable uses. | O12: 1 | P12: =+VLOOKUP(O12,References!$A$2:$F$29,2,0) -> Northey et al. (2013) | Q12: =+VLOOKUP(K12&L12,Unit_Normalization!$A$2:$D$24,4,0)*J12 -> 135.4 | R12: =+Table1[[#This Row],[TotalWater_m3_tonCu]]*Table1[[#This Row],[Grade ore Cu%]] -> 0.5416
A13: 12 | B13: Copper | C13: =+Northey2013!A14 -> Canada | D13: =+Northey2013!B14 -> Kidd Creek | E13: =+Northey2013!D14 -> VMS | F13: =VLOOKUP(+Northey2013!F14,Northey2013!$A$39:$B$41,2,0) -> Open Pit | G13: =+Northey2013!E14 -> Cu–Zn | H13: =+Northey2013!I14/100 -> 0.0207 | I13: 1 | J13: 76.7 | K13: kL | L13: t Cu | N13: water is used in various ways such as to control moisture content in slopes, dust suppression and to cool drilling and hauling equipment. Water is required in the beneficiation stage to ensure optimal grinding of ore, to allow transfer of concentrate slurry between unit processes and for flotation processes. Additionally, water may be used to cool heavy machinery and furnaces. A modest amount of water is also required for potable uses. | O13: 1 | P13: =+VLOOKUP(O13,References!$A$2:$F$29,2,0) -> Northey et al. (2013) | Q13: =+VLOOKUP(K13&L13,Unit_Normalization!$A$2:$D$24,4,0)*J13 -> 76.7 | R13: =+Table1[[#This Row],[TotalWater_m3_tonCu]]*Table1[[#This Row],[Grade ore Cu%]] -> 1.58769
... A32: 31 | B32: Copper | C32: =+Northey2013!A33 -> USA | D32: =+Northey2013!B33 -> Kennecott Utah | E32: =+Northey2013!D33 -> Porphyry | F32: =VLOOKUP(+Northey2013!F33,Northey2013!$A$39:$B$41,2,0) -> Open Pit | G32: =+Northey2013!E33 -> Cu–Au–Ag–Mo | H32: =+Northey2013!I33/100 -> 0.0059 | I32: 1 | J32: 9.8 | K32: kL | L32: t Cu | N32: water is used in various ways such as to control moisture content in slopes, dust suppression and to cool drilling and hauling equipment. Water is required in the beneficiation stage to ensure optimal grinding of ore, to allow transfer of concentrate slurry between unit processes and for flotation processes. Additionally, water may be used to cool heavy machinery and furnaces. A modest amount of water is also required for potable uses. | O32: 1 | P32: =+VLOOKUP(O32,References!$A$2:$F$29,2,0) -> Northey et al. (2013) | Q32: =+VLOOKUP(K32&L32,Unit_Normalization!$A$2:$D$24,4,0)*J32 -> 9.8 | R32: =+Table1[[#This Row],[TotalWater_m3_tonCu]]*Table1[[#This Row],[Grade ore Cu%]] -> 0.05782
A33: 32 | B33: Copper | C33: =+Lutter2025!A2 -> Africa | D33: =+Lutter2025!B2 -> Trident - Sentinel | E33: =VLOOKUP(Lutter2025!E2,Lutter2025!$A$46:$B$51,2,0) -> sediment hosted | F33: =+Lutter2025!D2 -> Open Pit | G33: =+VLOOKUP(Lutter2025!C2,Lutter2025!$A$54:$B$58,2,0) -> copper as main product | H33: 0.0049 | I33: S&P | J33: =+Lutter2025!H2 -> 302 | K33: L | L33: kg Cu | O33: 2 | P33: =+VLOOKUP(O33,References!$A$2:$F$29,2,0) -> Lutter et al. (2025) | Q33: =+VLOOKUP(K33&L33,Unit_Normalization!$A$2:$D$24,4,0)*J33 -> 302 | R33: =+Table1[[#This Row],[TotalWater_m3_tonCu]]*Table1[[#This Row],[Grade ore Cu%]] -> 1.4798
A34: 33 | B34: Copper | C34: =+Lutter2025!A3 -> Africa | D34: =+Lutter2025!B3 -> Kansanshi | E34: =VLOOKUP(Lutter2025!E3,Lutter2025!$A$46:$B$51,2,0) -> sediment hosted | F34: =+Lutter2025!D3 -> Combined | G34: =+VLOOKUP(Lutter2025!C3,Lutter2025!$A$54:$B$58,2,0) -> copper as main product | H34: 0.00584893 | I34: S&P | J34: =+Lutter2025!H3 -> 197 | K34: L | L34: kg Cu | O34: 2 | P34: =+VLOOKUP(O34,References!$A$2:$F$29,2,0) -> Lutter et al. (2025) | Q34: =+VLOOKUP(K34&L34,Unit_Normalization!$A$2:$D$24,4,0)*J34 -> 197 | R34: =+Table1[[#This Row],[TotalWater_m3_tonCu]]*Table1[[#This Row],[Grade ore Cu%]] -> 1.1522392
A35: 34 | B35: Copper | C35: =+Lutter2025!A4 -> Africa | D35: =+Lutter2025!B4 -> Lumwana | E35: =VLOOKUP(Lutter2025!E4,Lutter2025!$A$46:$B$51,2,0) -> sediment hosted | F35: =+Lutter2025!D4 -> Open Pit | G35: =+VLOOKUP(Lutter2025!C4,Lutter2025!$A$54:$B$58,2,0) -> copper as main product | H35: 0.0049 | I35: S&P | J35: =+Lutter2025!H4 -> 149 | K35: L | L35: kg Cu | O35: 2 | P35: =+VLOOKUP(O35,References!$A$2:$F$29,2,0) -> Lutter et al. (2025) | Q35: =+VLOOKUP(K35&L35,Unit_Normalization!$A$2:$D$24,4,0)*J35 -> 149 | R35: =+Table1[[#This Row],[TotalWater_m3_tonCu]]*Table1[[#This Row],[Grade ore Cu%]] -> 0.7301
A36: 35 | B36: Copper | C36: =+Lutter2025!A5 -> Africa | D36: =+Lutter2025!B5 -> Kamoto | E36: =VLOOKUP(Lutter2025!E5,Lutter2025!$A$46:$B$51,2,0) -> sediment hosted | F36: =+Lutter2025!D5 -> Combined | G36: =+VLOOKUP(Lutter2025!C5,Lutter2025!$A$54:$B$58,2,0) -> copper as main product | H36: 0.0088527519 | I36: S&P | J36: =+Lutter2025!H5 -> 49 | K36: L | L36: kg Cu | O36: 2 | P36: =+VLOOKUP(O36,References!$A$2:$F$29,2,0) -> Lutter et al. (2025) | Q36: =+VLOOKUP(K36&L36,Unit_Normalization!$A$2:$D$24,4,0)*J36 -> 49 | R36: =+Table1[[#This Row],[TotalWater_m3_tonCu]]*Table1[[#This Row],[Grade ore Cu%]] -> 0.43378484
A37: 36 | B37: Copper | C37: =+Lutter2025!A6 -> Africa | D37: =+Lutter2025!B6 -> Tenke Fungurume | E37: =VLOOKUP(Lutter2025!E6,Lutter2025!$A$46:$B$51,2,0) -> sediment hosted | F37: =+Lutter2025!D6 -> Open Pit | G37: =+VLOOKUP(Lutter2025!C6,Lutter2025!$A$54:$B$58,2,0) -> copper as main product | H37: 0.0283 | I37: S&P | J37: =+Lutter2025!H6 -> 72 | K37: L | L37: kg Cu | O37: 2 | P37: =+VLOOKUP(O37,References!$A$2:$F$29,2,0) -> Lutter et al. (2025) | Q37: =+VLOOKUP(K37&L37,Unit_Normalization!$A$2:$D$24,4,0)*J37 -> 72 | R37: =+Table1[[#This Row],[TotalWater_m3_tonCu]]*Table1[[#This Row],[Grade ore Cu%]] -> 2.0376
A38: 37 | B38: Copper | C38: =+Lutter2025!A7 -> East Asia | D38: =+Lutter2025!B7 -> Grasberg | E38: =VLOOKUP(Lutter2025!E7,Lutter2025!$A$46:$B$51,2,0) -> porphyry deposit | F38: =+Lutter2025!D7 -> Combined | G38: =+VLOOKUP(Lutter2025!C7,Lutter2025!$A$54:$B$58,2,0) -> copper as main product | H38: 0.0122 | I38: S&P | J38: =+Lutter2025!H7 -> 163 | K38: L | L38: kg Cu | O38: 2 | P38: =+VLOOKUP(O38,References!$A$2:$F$29,2,0) -> Lutter et al. (2025) | Q38: =+VLOOKUP(K38&L38,Unit_Normalization!$A$2:$D$24,4,0)*J38 -> 163 | R38: =+Table1[[#This Row],[TotalWater_m3_tonCu]]*Table1[[#This Row],[Grade ore Cu%]] -> 1.9886
A39: 38 | B39: Copper | C39: =+Lutter2025!A8 -> East Asia | D39: =+Lutter2025!B8 -> Erdenet | E39: =VLOOKUP(Lutter2025!E8,Lutter2025!$A$46:$B$51,2,0) -> porphyry deposit | F39: =+Lutter2025!D8 -> Open Pit | G39: =+VLOOKUP(Lutter2025!C8,Lutter2025!$A$54:$B$58,2,0) -> copper as main product | H39: 0.005285 | I39: S&P | J39: =+Lutter2025!H8 -> 192 | K39: L | L39: kg Cu | O39: 2 | P39: =+VLOOKUP(O39,References!$A$2:$F$29,2,0) -> Lutter et al. (2025) | Q39: =+VLOOKUP(K39&L39,Unit_Normalization!$A$2:$D$24,4,0)*J39 -> 192 | R39: =+Table1[[#This Row],[TotalWater_m3_tonCu]]*Table1[[#This Row],[Grade ore Cu%]] -> 1.01472
A40: 39 | B40: Copper | C40: =+Lutter2025!A9 -> East Asia | D40: =+Lutter2025!B9 -> Dexing Complex | E40: =VLOOKUP(Lutter2025!E9,Lutter2025!$A$46:$B$51,2,0) -> porphyry deposit | F40: =+Lutter2025!D9 -> Combined | G40: =+VLOOKUP(Lutter2025!C9,Lutter2025!$A$54:$B$58,2,0) -> copper as main product | H40: 0.003957 | I40: S&P | J40: =+Lutter2025!H9 -> 162 | K40: L | L40: kg Cu | O40: 2 | P40: =+VLOOKUP(O40,References!$A$2:$F$29,2,0) -> Lutter et al. (2025) | Q40: =+VLOOKUP(K40&L40,Unit_Normalization!$A$2:$D$24,4,0)*J40 -> 162 | R40: =+Table1[[#This Row],[TotalWater_m3_tonCu]]*Table1[[#This Row],[Grade ore Cu%]] -> 0.641034
A41: 40 | B41: Copper | C41: =+Lutter2025!A10 -> East Asia | D41: =+Lutter2025!B10 -> Letpadaung Mountain | E41: =VLOOKUP(Lutter2025!E10,Lutter2025!$A$46:$B$51,2,0) -> iron oxide copper-gold deposit | F41: =+Lutter2025!D10 -> Open Pit | G41: =+VLOOKUP(Lutter2025!C10,Lutter2025!$A$54:$B$58,2,0) -> #N/A | H41: 0.00389263 | I41: S&P | J41: =+Lutter2025!H10 -> 199 | K41: L | L41: kg Cu | O41: 2 | P41: =+VLOOKUP(O41,References!$A$2:$F$29,2,0) -> Lutter et al. (2025) | Q41: =+VLOOKUP(K41&L41,Unit_Normalization!$A$2:$D$24,4,0)*J41 -> 199 | R41: =+Table1[[#This Row],[TotalWater_m3_tonCu]]*Table1[[#This Row],[Grade ore Cu%]] -> 0.77463337
A42: 41 | B42: Copper | C42: =+Lutter2025!A11 -> East Asia | D42: =+Lutter2025!B11 -> Batu Hijau | E42: =VLOOKUP(Lutter2025!E11,Lutter2025!$A$46:$B$51,2,0) -> porphyry deposit | F42: =+Lutter2025!D11 -> Open Pit | G42: =+VLOOKUP(Lutter2025!C11,Lutter2025!$A$54:$B$58,2,0) -> copper as main product | H42: 0.004518 | I42: S&P | J42: =+Lutter2025!H11 -> 129 | K42: L | L42: kg Cu | O42: 2 | P42: =+VLOOKUP(O42,References!$A$2:$F$29,2,0) -> Lutter et al. (2025) | Q42: =+VLOOKUP(K42&L42,Unit_Normalization!$A$2:$D$24,4,0)*J42 -> 129 | R42: =+Table1[[#This Row],[TotalWater_m3_tonCu]]*Table1[[#This Row],[Grade ore Cu%]] -> 0.582822
A43: 42 | B43: Copper | C43: =+Lutter2025!A12 -> Europe & Central Asia | D43: =+Lutter2025!B12 -> Kola Division | E43: =VLOOKUP(Lutter2025!E12,Lutter2025!$A$46:$B$51,2,0) -> unknown type of deposit | F43: =+Lutter2025!D12 -> Combined | G43: =+VLOOKUP(Lutter2025!C12,Lutter2025!$A$54:$B$58,2,0) -> copper as by-product | I43: S&P | J43: =+Lutter2025!H12 -> 321 | K43: L | L43: kg Cu | O43: 2 | P43: =+VLOOKUP(O43,References!$A$2:$F$29,2,0) -> Lutter et al. (2025) | Q43: =+VLOOKUP(K43&L43,Unit_Normalization!$A$2:$D$24,4,0)*J43 -> 321
A44: 43 | B44: Copper | C44: =+Lutter2025!A13 -> Europe & Central Asia | D44: =+Lutter2025!B13 -> Polar Division | E44: =VLOOKUP(Lutter2025!E13,Lutter2025!$A$46:$B$51,2,0) -> other type of deposit | F44: =+Lutter2025!D13 -> Combined | G44: =+VLOOKUP(Lutter2025!C13,Lutter2025!$A$54:$B$58,2,0) -> copper as by-product | I44: S&P | J44: =+Lutter2025!H13 -> 74 | K44: L | L44: kg Cu | O44: 2 | P44: =+VLOOKUP(O44,References!$A$2:$F$29,2,0) -> Lutter et al. (2025) | Q44: =+VLOOKUP(K44&L44,Unit_Normalization!$A$2:$D$24,4,0)*J44 -> 74
A45: 44 | B45: Copper | C45: =+Lutter2025!A14 -> Europe & Central Asia | D45: =+Lutter2025!B14 -> Rudna | E45: =VLOOKUP(Lutter2025!E14,Lutter2025!$A$46:$B$51,2,0) -> sediment hosted | F45: =+Lutter2025!D14 -> Underground | G45: =+VLOOKUP(Lutter2025!C14,Lutter2025!$A$54:$B$58,2,0) -> copper as main product | H45: 0.0202 | I45: https://kghm.com/en/our-business/mining-and-enrichment/rudna | J45: =+Lutter2025!H14 -> 135 | K45: L | L45: kg Cu | O45: 2 | P45: =+VLOOKUP(O45,References!$A$2:$F$29,2,0) -> Lutter et al. (2025) | Q45: =+VLOOKUP(K45&L45,Unit_Normalization!$A$2:$D$24,4,0)*J45 -> 135 | R45: =+Table1[[#This Row],[TotalWater_m3_tonCu]]*Table1[[#This Row],[Grade ore Cu%]] -> 2.727
A46: 45 | B46: Copper | C46: =+Lutter2025!A15 -> Europe & Central Asia | D46: =+Lutter2025!B15 -> Aitik | E46: =VLOOKUP(Lutter2025!E15,Lutter2025!$A$46:$B$51,2,0) -> porphyry deposit | F46: =+Lutter2025!D15 -> Open Pit | G46: =+VLOOKUP(Lutter2025!C15,Lutter2025!$A$54:$B$58,2,0) -> copper as main product | H46: 0.0018 | I46: S&P | J46: =+Lutter2025!H15 -> 267 | K46: L | L46: kg Cu | O46: 2 | P46: =+VLOOKUP(O46,References!$A$2:$F$29,2,0) -> Lutter et al. (2025) | Q46: =+VLOOKUP(K46&L46,Unit_Normalization!$A$2:$D$24,4,0)*J46 -> 267 | R46: =+Table1[[#This Row],[TotalWater_m3_tonCu]]*Table1[[#This Row],[Grade ore Cu%]] -> 0.4806
A47: 46 | B47: Copper | C47: =+Lutter2025!A16 -> Europe & Central Asia | D47: =+Lutter2025!B16 -> Zhezkazgan Complex | E47: =VLOOKUP(Lutter2025!E16,Lutter2025!$A$46:$B$51,2,0) -> sediment hosted | F47: =+Lutter2025!D16 -> Combined | G47: =+VLOOKUP(Lutter2025!C16,Lutter2025!$A$54:$B$58,2,0) -> copper as main product | H47: 0.0127 | I47: S&P | J47: =+Lutter2025!H16 -> 142 | K47: L | L47: kg Cu | O47: 2 | P47: =+VLOOKUP(O47,References!$A$2:$F$29,2,0) -> Lutter et al. (2025) | Q47: =+VLOOKUP(K47&L47,Unit_Normalization!$A$2:$D$24,4,0)*J47 -> 142 | R47: =+Table1[[#This Row],[TotalWater_m3_tonCu]]*Table1[[#This Row],[Grade ore Cu%]] -> 1.8034
A48: 47 | B48: Copper | C48: =+Lutter2025!A17 -> Latin America & Caribbean | D48: =+Lutter2025!B17 -> Cobre Panama | E48: =VLOOKUP(Lutter2025!E17,Lutter2025!$A$46:$B$51,2,0) -> porphyry deposit | F48: =+Lutter2025!D17 -> Open Pit | G48: =+VLOOKUP(Lutter2025!C17,Lutter2025!$A$54:$B$58,2,0) -> copper as main product | H48: 0.0047 | I48: S&P | J48: =+Lutter2025!H17 -> 826 | K48: L | L48: kg Cu | O48: 2 | P48: =+VLOOKUP(O48,References!$A$2:$F$29,2,0) -> Lutter et al. (2025) | Q48: =+VLOOKUP(K48&L48,Unit_Normalization!$A$2:$D$24,4,0)*J48 -> 826 | R48: =+Table1[[#This Row],[TotalWater_m3_tonCu]]*Table1[[#This Row],[Grade ore Cu%]] -> 3.8822
A49: 48 | B49: Copper | C49: =+Lutter2025!A18 -> Latin America & Caribbean | D49: =+Lutter2025!B18 -> Escondida | E49: =VLOOKUP(Lutter2025!E18,Lutter2025!$A$46:$B$51,2,0) -> porphyry deposit | F49: =+Lutter2025!D18 -> Open Pit | G49: =+VLOOKUP(Lutter2025!C18,Lutter2025!$A$54:$B$58,2,0) -> copper as main product | H49: 0.008332 | I49: S&P | J49: =+Lutter2025!H18 -> 85 | K49: L | L49: kg Cu | O49: 2 | P49: =+VLOOKUP(O49,References!$A$2:$F$29,2,0) -> Lutter et al. (2025) | Q49: =+VLOOKUP(K49&L49,Unit_Normalization!$A$2:$D$24,4,0)*J49 -> 85 | R49: =+Table1[[#This Row],[TotalWater_m3_tonCu]]*Table1[[#This Row],[Grade ore Cu%]] -> 0.70822
A50: 49 | B50: Copper | C50: =+Lutter2025!A19 -> Latin America & Caribbean | D50: =+Lutter2025!B19 -> El Teniente | E50: =VLOOKUP(Lutter2025!E19,Lutter2025!$A$46:$B$51,2,0) -> porphyry deposit | F50: =+Lutter2025!D19 -> Combined | G50: =+VLOOKUP(Lutter2025!C19,Lutter2025!$A$54:$B$58,2,0) -> copper as main product | H50: 0.0085 | I50: S&P | J50: =+Lutter2025!H19 -> 151 | K50: L | L50: kg Cu | O50: 2 | P50: =+VLOOKUP(O50,References!$A$2:$F$29,2,0) -> Lutter et al. (2025) | Q50: =+VLOOKUP(K50&L50,Unit_Normalization!$A$2:$D$24,4,0)*J50 -> 151 | R50: =+Table1[[#This Row],[TotalWater_m3_tonCu]]*Table1[[#This Row],[Grade ore Cu%]] -> 1.2835
A51: 50 | B51: Copper | C51: =+Lutter2025!A20 -> Latin America & Caribbean | D51: =+Lutter2025!B20 -> Chuquicamata | E51: =VLOOKUP(Lutter2025!E20,Lutter2025!$A$46:$B$51,2,0) -> porphyry deposit | F51: =+Lutter2025!D20 -> Open Pit | G51: =+VLOOKUP(Lutter2025!C20,Lutter2025!$A$54:$B$58,2,0) -> copper as main product | H51: 0.005925 | I51: S&P | J51: =+Lutter2025!H20 -> 163 | K51: L | L51: kg Cu | O51: 2 | P51: =+VLOOKUP(O51,References!$A$2:$F$29,2,0) -> Lutter et al. (2025) | Q51: =+VLOOKUP(K51&L51,Unit_Normalization!$A$2:$D$24,4,0)*J51 -> 163 | R51: =+Table1[[#This Row],[TotalWater_m3_tonCu]]*Table1[[#This Row],[Grade ore Cu%]] -> 0.965775
A52: 51 | B52: Copper | C52: =+Lutter2025!A21 -> Latin America & Caribbean | D52: =+Lutter2025!B21 -> Cerro Verde | E52: =VLOOKUP(Lutter2025!E21,Lutter2025!$A$46:$B$51,2,0) -> porphyry deposit | F52: =+Lutter2025!D21 -> Open Pit | G52: =+VLOOKUP(Lutter2025!C21,Lutter2025!$A$54:$B$58,2,0) -> copper as main product | H52: 0.0034 | I52: S&P | J52: =+Lutter2025!H21 -> 118 | K52: L | L52: kg Cu | O52: 2 | P52: =+VLOOKUP(O52,References!$A$2:$F$29,2,0) -> Lutter et al. (2025) | Q52: =+VLOOKUP(K52&L52,Unit_Normalization!$A$2:$D$24,4,0)*J52 -> 118 | R52: =+Table1[[#This Row],[TotalWater_m3_tonCu]]*Table1[[#This Row],[Grade ore Cu%]] -> 0.4012
A53: 52 | B53: Copper | C53: =+Lutter2025!A22 -> North America | D53: =+Lutter2025!B22 -> Morenci | E53: =VLOOKUP(Lutter2025!E22,Lutter2025!$A$46:$B$51,2,0) -> porphyry deposit | F53: =+Lutter2025!D22 -> Open Pit | G53: =+VLOOKUP(Lutter2025!C22,Lutter2025!$A$54:$B$58,2,0) -> copper as main product | H53: 0.0028 | I53: S&P | J53: =+Lutter2025!H22 -> 115 | K53: L | L53: kg Cu | O53: 2 | P53: =+VLOOKUP(O53,References!$A$2:$F$29,2,0) -> Lutter et al. (2025) | Q53: =+VLOOKUP(K53&L53,Unit_Normalization!$A$2:$D$24,4,0)*J53 -> 115 | R53: =+Table1[[#This Row],[TotalWater_m3_tonCu]]*Table1[[#This Row],[Grade ore Cu%]] -> 0.322
A54: 53 | B54: Copper | C54: =+Lutter2025!A23 -> North America | D54: =+Lutter2025!B23 -> Kennecott | E54: =VLOOKUP(Lutter2025!E23,Lutter2025!$A$46:$B$51,2,0) -> porphyry deposit | F54: =+Lutter2025!D23 -> Combined | G54: =+VLOOKUP(Lutter2025!C23,Lutter2025!$A$54:$B$58,2,0) -> copper as main product | H54: 0.0302 | I54: https://minedocs.com/28/Kennecott-NRS-MR-06202023.pdf | J54: =+Lutter2025!H23 -> 123 | K54: L | L54: kg Cu | O54: 2 | P54: =+VLOOKUP(O54,References!$A$2:$F$29,2,0) -> Lutter et al. (2025) | Q54: =+VLOOKUP(K54&L54,Unit_Normalization!$A$2:$D$24,4,0)*J54 -> 123 | R54: =+Table1[[#This Row],[TotalWater_m3_tonCu]]*Table1[[#This Row],[Grade ore Cu%]] -> 3.7146
A55: 54 | B55: Copper | C55: =+Lutter2025!A24 -> North America | D55: =+Lutter2025!B24 -> Highland Valley | E55: =VLOOKUP(Lutter2025!E24,Lutter2025!$A$46:$B$51,2,0) -> porphyry deposit | F55: =+Lutter2025!D24 -> Open Pit | G55: =+VLOOKUP(Lutter2025!C24,Lutter2025!$A$54:$B$58,2,0) -> copper as main product | H55: 0.003 | I55: S&P | J55: =+Lutter2025!H24 -> 161 | K55: L | L55: kg Cu | O55: 2 | P55: =+VLOOKUP(O55,References!$A$2:$F$29,2,0) -> Lutter et al. (2025) | Q55: =+VLOOKUP(K55&L55,Unit_Normalization!$A$2:$D$24,4,0)*J55 -> 161 | R55: =+Table1[[#This Row],[TotalWater_m3_tonCu]]*Table1[[#This Row],[Grade ore Cu%]] -> 0.483
A56: 55 | B56: Copper | C56: =+Lutter2025!A25 -> North America | D56: =+Lutter2025!B25 -> Mission | E56: =VLOOKUP(Lutter2025!E25,Lutter2025!$A$46:$B$51,2,0) -> porphyry deposit | F56: =+Lutter2025!D25 -> Combined | G56: =+VLOOKUP(Lutter2025!C25,Lutter2025!$A$54:$B$58,2,0) -> copper as main product | H56: 0.00378 | I56: S&P | J56: =+Lutter2025!H25 -> 379 | K56: L | L56: kg Cu | O56: 2 | P56: =+VLOOKUP(O56,References!$A$2:$F$29,2,0) -> Lutter et al. (2025) | Q56: =+VLOOKUP(K56&L56,Unit_Normalization!$A$2:$D$24,4,0)*J56 -> 379 | R56: =+Table1[[#This Row],[TotalWater_m3_tonCu]]*Table1[[#This Row],[Grade ore Cu%]] -> 1.43262
... A67: 66 | B67: Copper | C67: =+Lutter2025!A36 -> South & west Asia | D67: =+Lutter2025!B36 -> Saindak | E67: =VLOOKUP(Lutter2025!E36,Lutter2025!$A$46:$B$51,2,0) -> porphyry deposit | F67: =+Lutter2025!D36 -> Open Pit | G67: =+VLOOKUP(Lutter2025!C36,Lutter2025!$A$54:$B$58,2,0) -> copper as main product | H67: 0.015799718 | I67: S&P | J67: =+Lutter2025!H36 -> 160 | K67: L | L67: kg Cu | O67: 2 | P67: =+VLOOKUP(O67,References!$A$2:$F$29,2,0) -> Lutter et al. (2025) | Q67: =+VLOOKUP(K67&L67,Unit_Normalization!$A$2:$D$24,4,0)*J67 -> 160 | R67: =+Table1[[#This Row],[TotalWater_m3_tonCu]]*Table1[[#This Row],[Grade ore Cu%]] -> 2.5279549
A68: 67 | B68: Copper | C68: Laos | F68: Open Pit | G68: Green + Blue + Grey water | H68: 0.0054 | I68: https://panaust.com.au/wp-content/uploads/2024/02/2018-Business-Review-and-Sustainability-Report.pdf | J68: 1110.14 | K68: m3 | L68: ton Cu | O68: 3 | P68: =+VLOOKUP(O68,References!$A$2:$F$29,2,0) -> Islam et al. (2020) | Q68: =+VLOOKUP(K68&L68,Unit_Normalization!$A$2:$D$24,4,0)*J68 -> 1110.14 | R68: =+Table1[[#This Row],[TotalWater_m3_tonCu]]*Table1[[#This Row],[Grade ore Cu%]] -> 5.994756
...

Sheet References
A1: ID | B1: Name | C1: Full cite | D1: Year | E1: DOI | F1: Notes | G1: Type
A2: 1 | B2: Northey et al. (2013) | C2: Northey, S., Haque, N., & Mudd, G. (2013). Using sustainability reporting to assess the environmental footprint of copper mining. Journal of Cleaner Production, 40, 118-128. | D2: 2013 | E2: https://doi.org/10.1016/j.jclepro.2012.09.027 | F2: Extensive amount of data on copper projects, but from 10 years ago. | G2: Water consumption
A3: 2 | B3: Lutter et al. (2025) | C3: Lutter, S., Maus, V., Luckeneder, S., & Tost, M. (2025). Increasing Water Use in Global Copper Production Threatens Freshwater Availability. WU Vienna University of Economics and Business. Ecological Economic Papers Vol. 49/2025 https://doi.org/10.57938/441b6e21-b914-4565-a2af-623f78ed92c6 | D3: 2025 | E3: https://doi.org/10.57938/441b6e21-b914-4565-a2af-623f78ed92c6 | G3: Water use (consumption)
A4: 3 | B4: Islam et al. (2020) | C4: Islam, K., & Murakami, S. (2020). Accounting for water footprint of an open-pit copper mine. Sustainability, 12(22), 9660. | D4: 2020 | E4: https://doi.org/10.3390/su12229660 | G4: Green + Blue + Grey water (only one data point)
A5: 4 | B5: Peña et al. (2014) | C5: Peña, C. A., & Huijbregts, M. A. (2014). The blue water footprint of primary copper production in northern Chile. Journal of Industrial Ecology, 18(1), 49-58. | D5: 2014 | E5: https://doi.org/10.1111/jiec.12036 | G5: Water consumption
A6: 5 | B6: Rinne et al. (2021) | C6: Rinne, M., Elomaa, H., & Lundström, M. (2021). Life cycle assessment and process simulation of prospective battery-grade cobalt sulfate production from Co-Au ores in Finland. The International Journal of Life Cycle Assessment, 26(11), 2127-2142. | D6: 2021 | E6: https://doi.org/10.1007/s11367-021-01965-3 | G6: 0 data points
A7: 6 | B7: Gunson (2013) | C7: Gunson, A. J. (2013). Quantifying, reducing and improving mine water use (Doctoral dissertation, University of British Columbia). | D7: 2013 | E7: 10.14288/1.0071942 | G7: Water withdrawal
A8: 7 | B8: Mudd (2008) | C8: Mudd, G. M. (2008). Sustainability reporting and water resources: a preliminary assessment of embodied water and sustainable mining. Mine Water and the Environment, 27(3), 136-144. | D8: 2008 | E8: https://doi.org/10.1007/s10230-008-0037-5 | G8: Water consumption
A9: 8 | B9: Dai et al. (2018) | C9: Dai, Q., Kelly, J. C., & Elgowainy, A. (2018). Cobalt life cycle analysis update for the GREET Model. Argonne National Laboratory. | D9: 2018 | G9: Water consumption

Sheet Unit_Normalization
A1: Key | B1: Unit num | C1: Unit den | D1: Factor_m3perTon
A2: =+B2&C2 -> kLt Cu | B2: kL | C2: t Cu | D2: 1
A3: =+B3&C3 -> Lkg Cu | B3: L | C3: kg Cu | D3: 1
A4: =+B4&C4 -> m3ton Cu | B4: m3 | C4: ton Cu | D4: 1
A5: =+B5&C5 -> m3kg Co | B5: m3 | C5: kg Co | D5: 1000
A6: =+B6&C6 -> m3ton Ni | B6: m3 | C6: ton Ni | D6: 1
A7: =+B7&C7 -> m3ton Co | B7: m3 | C7: ton Co | D7: 1

Sheet Northey2013
B1: Operation | C1: Operating company | D1: Deposit type | E1: Metals extracted | F1: Mine type | G1: Process | H1: kt ore/yr | I1: % Cu | J1: t Cu/year | K1: Electricity source | L1: Direct | M1: Indirect GJ/t Cu | N1: Total GJ/t Cu | O1: Total | P1: kL/t Cu | Q1: Weighting Cu % | R1: Period
A2: Country | L2: GJ/t Cu | O2: t CO2−e/t Cu
A3: Australia | B3: Cadia-Ridgeway | C3: Newcrest | D3: Porphyry | E3: Au–Cu | F3: O/U | G3: MC | H3: 22317 | I3: 0.33 | J3: 64228 | K3: Coal | L3: 12.4(7) | M3: 16.0(7) | N3: 28.4(7) | O3: 5.2(7) | P3: 49.0(7) | Q3: 43 | R3: 2003/04–2009/10
A4: Australia | B4: Ernest Henry | C4: Xstrata | D4: IOCG | E4: Cu–Au | F4: OP | G4: MC | H4: 10232 | I4: 0.98 | J4: 95130 | K4: Gas | L4: 16.5(4) | M4: 8.0(4) | N4: 23.2(6) | O4: 2.3(6) | P4: 42.3(7) | Q4: 84.8 | R4: 2002–2010
A5: Australia | B5: Golden Grove | C5: MMG | D5: VMS | E5: Ag–Pb–Zn–Cu | F5: UG | G5: MC | H5: 1530 | I5: 1.85 | J5: 19446 | K5: Hydro | L5: 4.0(4) | M5: 5.9(3) | N5: 10.1(3) | O5: 1.7(4) | P5: 33.0(3) | Q5: 35.9 | R5: 2005–2010
A6: Australia | B6: Mount Isa | C6: Xstrata | D6: SedEx | E6: Cu | F6: UG | G6: MCS | H6: 5787 | I6: 3.21 | J6: 222261 | K6: Coal, gas | L6: 10.1(4) | M6: 12.7(4) | N6: 21.2(6) | O6: 2.1(6) | P6: 19.5(7) | Q6: 100 | R6: 2002–2010
A7: Australia | B7: Northparkes | C7: Rio Tinto80% | D7: Porphyry | E7: Cu–Au | F7: O/U | G7: MC | H7: 5290 | I7: 0.78 | J7: 40678 | K7: Coal | L7: 7.3(3) | M7: 19.5(3) | N7: 19.4(5) | O7: 4.1(5) | P7: 74.0(8) | Q7: 85.7 | R7: 2003–2010
A8: Australia | B8: Olympic Dam | C8: BHP Billiton | D8: IOCG | E8: Cu–Au–Ag–U | F8: UG | G8: MCSRL | H8: 7841 | I8: 2.46 | J8: 136827 | K8: Coal, wind | L8: 11.1(6) | M8: 14.8(7) | N8: 27.2(19) | O8: 5.0(16) | P8: 46.6(14) | Q8: 95.3 | R8: 1991–2010
A9: Australia | B9: Prominent Hill | C9: OZ Minerals | D9: IOCG | E9: Cu–Au–Ag | F9: OP | G9: MC | H9: 8038 | I9: 1.54 | J9: 104241 | K9: Coal, wind | L9: 9.0(2) | M9: 8.7(2) | N9: 17.7(2) | O9: 2.2(2) | P9: 39.8(2) | Q9: 80.9 | R9: 2009–2010
A10: Australia | B10: Rosebery | C10: MMG | D10: VMS | E10: Ag–Pb–Zn–Cu–Au | F10: UG | G10: MC | H10: 760 | I10: 0.36 | J10: 1985 | K10: Hydro | L10: 6.1(2) | M10: 12.8(2) | N10: 18.8(2) | O10: 1.2(2) | P10: 1046.9(1) | Q10: 10.5 | R10: 2009–2010
A11: Australia | B11: Telfer | C11: Newcrest | D11: OGC | E11: Au–Cu | F11: O/U | G11: MC | H11: 17903 | I11: 0.24 | J11: 30519 | K11: Gas | L11: 20.9(6) | M11: 19.8(6) | N11: 40.6(6) | O11: 4.7(6) | P11: 161.1(6) | Q11: 29.4 | R11: 2004/05–2009/10
A12: Argentina | B12: Alumbrera | C12: Xstrata50% | D12: Porphyry | E12: Cu–Au | F12: OP | G12: MCL | H12: 36127 | I12: 0.55 | J12: 174078 | K12: GAS, Hydro | L12: 23.9(4) | M12: 13.4(5) | N12: 37.3(4) | P12: 91.3(6) | Q12: 68 | R12: 2002–2010
A13: Canada | B13: Highland Valley | C13: Teck | D13: Porphyry | E13: Cu–Mo | F13: UG | G13: MC | H13: 48882 | I13: 0.4 | J13: 164827 | K13: Hydro | L13: 6.6(4) | M13: 17.1(4) | N13: 23.7(4) | O13: 0.9(4) | P13: 135.4(2) | Q13: 82.3 | R13: 2004–2007
A14: Canada | B14: Kidd Creek | C14: Xstrata | D14: VMS | E14: Cu–Zn | F14: OP | G14: MCSR | H14: 2451 | I14: 2.07 | J14: 87009 | K14: Hydro/Nuclear | N14: 20.0(2) | O14: 2.3(2) | P14: 76.7(2) | Q14: 56.2 | R14: 2006–2010
A15: Chile | B15: Andina | C15: Codelco | D15: Breccia-Porphyry | E15: Cu–Mo | F15: O/U | G15: MC | H15: 23446 | I15: 1.05 | J15: 226932 | K15: SIC | L15: 3.1(9) | M15: 8.7(10) | N15: 11.8 (9) | O15: 1.0(9) | P15: 99.4(7) | Q15: 91.3 | R15: 2001–2010
A16: Chile | B16: Codelco Norte | C16: Codelco | D16: Porphyry | E16: Cu–Mo | F16: OP | G16: MCSL | H16: 126120 | I16: 0.83 | J16: 888618 | K16: SING | L16: 10.8(9) | M16: 9.4(10) | N16: 17.1(9) | O16: 3.1(9) | P16: 53.3(8) | Q16: 87.4 | R16: 1999–2010
A17: Chile | B17: Collahuasi | C17: Xstrata-Anglo | D17: Porphyry | E17: Cu–Mo–Au–Ag | F17: OP | G17: MCL | H17: 44422 | I17: 1.12 | J17: 479263 | K17: SING | L17: 5.9(4) | M17: 9.1(4) | N17: 15.0(4) | O17: 2.5(4) | P17: 31.9(2) | Q17: 95 | R17: 2006–2010
A18: Chile | B18: El Soldado | C18: Anglo American | D18: IOCG | E18: Cu | F18: O/U | G18: MCL | H18: 7995 | I18: 1 | J18: 62626 | K18: SIC | N18: 27.9(7) | O18: 2.0(7) | P18: 48.2(7) | Q18: 100 | R18: 2003–2009
A19: Chile | B19: El Teniente | C19: Codelco | D19: Breccia-Porphyry | E19: Cu–Mo | F19: UG | G19: MCS | H19: 44053 | I19: 1 | J19: 409692 | K19: SIC | L19: 5.2(9) | M19: 14.1(10) | N19: 19.3(9) | O19: 1.4(9) | P19: 139.7(7) | Q19: 92.4 | R19: 1999–2010
A20: Chile | B20: Escondida | C20: BHP57.5% | D20: Porphyry | E20: Cu–Au–Ag | F20: OP | G20: MCL | H20: 116425 | I20: 1.25 | J20: 1242644 | K20: SING | L20: 4.4(6) | M20: 7.5(6) | N20: 11.9(6) | O20: 1.7(6) | P20: 52.5(6) | Q20: 97.6 | R20: 2003–2008
A21: Chile | B21: Lomas Bayas | C21: Xstrata | D21: Porphyry | E21: Cu | F21: OP | G21: MH | H21: 41834 | I21: 0.31 | J21: 65937 | K21: SING | L21: 14.3(3) | M21: 12.6(3) | N21: 26.9(5) | P21: 75.5(3) | Q21: 100 | R21: 2006–2010
A22: Chile | B22: Los Bronces | C22: Anglo American | D22: Breccia- Porphyry | E22: Cu–Mo | F22: OP | G22: MCL | H22: 20469 | I22: 1.06 | J22: 228300 | K22: SIC | N22: 16.9(7) | O22: 1.1(7) | P22: 80.7(7) | Q22: 90.7 | R22: 2003–2009
A23: Chile | B23: Mantos Blancos | C23: Anglo American | D23: IOCG | E23: Cu | F23: OP | G23: MCL | H23: 14924 | I23: 0.69 | J23: 89957 | K23: Diesel, SING | N23: 47.2(7) | O23: 3.1(7) | P23: 226.5(7) | Q23: 100 | R23: 2003–2009
A24: Chile | B24: Mantoverde | C24: Anglo American | D24: IOCG | E24: Cu | F24: OP | G24: ML | H24: 14418 | I24: 0.56 | J24: 61093 | K24: SIC | N24: 22.8(7) | O24: 2.3(7) | P24: 46.6(7) | Q24: 100 | R24: 2003–2009
A25: Chile | B25: Salvador | C25: Codelco | D25: Porphyry | E25: Cu–Mo | F25: O/U | G25: MCSL | H25: 16704 | I25: 0.59 | J25: 74379 | K25: SIC | L25: 20.2(9) | M25: 23.4(10) | N25: 41.5(9) | O25: 3.5(9) | P25: 321.3(8) | Q25: 89.2 | R25: 1999–2010
A26: Chile | B26: Quebrada Blanca | C26: Teck76% | D26: Porphyry | E26: Cu–Zn | F26: OP | G26: ML | H26: 17626 | I26: 0.86 | J26: 85000 | K26: Diesel, SING | L26: 51.1(1) | M26: 0.6(1) | N26: 51.6(1) | O26: 3.9(1) | P26: 21.9(1) | Q26: 94.3 | R26: 2008
A27: Finland | B27: Pyhasalmi | C27: Inmet Mining | D27: VMS | E27: Zn–Cu | F27: UG | G27: MC | H27: 1374 | I27: 1.08 | J27: 16650 | L27: 4.5(7) | M27: 10.4(7) | N27: 14.9(6) | O27: 0.4(5) | P27: 211.0(7) | Q27: 51.8 | R27: 2005–2010
A28: Laos | B28: Sepon | C28: MMG | D28: Hybrid VMS-SedEx | E28: Cu–Au | F28: OP | G28: ML | H28: 3646 | I28: 1.99 | J28: 53370 | K28: Hydro | L28: 12.6(4) | M28: 13.7(4) | N28: 26.4(4) | O28: 2.8(4) | P28: 34.0(5) | Q28: 79 | R28: 2005–2010
A29: South Africa | B29: Palabora | C29: Palabora Mining Company | D29: Carbonatitic | E29: Cu | F29: UG | G29: MCSR | H29: 16932 | I29: 0.61 | J29: 77656 | K29: Coal | L29: 34.5(6) | M29: 20.4(6) | N29: 55.5(10) | O29: 8.5(10) | P29: 94.4(11) | Q29: 70.8 | R29: 2000–2010
A30: Turkey | B30: Cayeli | C30: Inmet Mining | D30: VMS | E30: Cu–Zn | F30: UG | G30: MC | H30: 967 | I30: 3.78 | J30: 30229 | L30: 1.5(7) | M30: 5.3(7) | N30: 6.7(7) | O30: 1.0(7) | P30: 87.3(7) | Q30: 65.7 | R30: 2003–2009
A31: Peru | B31: Tintaya | C31: Xstrata | D31: Skarn | E31: Cu–Au | F31: OP | G31: MCL | H31: 6944 | I31: 1.34 | J31: 103179 | K31: Hydro | L31: 21.6(1) | M31: 9.1(5) | N31: 31.4(1) | P31: 42.5(5) | Q31: 95.7 | R31: 2006–2010
A32: PNG | B32: Ok Tedi | C32: OTML | D32: Porphyry | E32: Cu–Au–Ag | F32: OP | G32: MC | H32: 24945 | I32: 0.83 | J32: 176460 | K32: Hydro | L32: 6.8(6) | M32: 8.1(4) | N32: 15.8(5) | O32: 1.2(6) | P32: 38.8(7) | Q32: 69.6 | R32: 2003–2010
A33: USA | B33: Kennecott Utah | C33: Rio Tinto | D33: Porphyry | E33: Cu–Au–Ag–Mo | F33: OP | G33: MCSR | H33: 48676 | I33: 0.59 | J33: 242122 | K33: Coal | N33: 47.0(8) | O33: 4.3(8) | P33: 9.8(7) | Q33: 58 | R33: 2003–2010
A38: Dict
A39: O/U | B39: Combined
A40: OP | B40: Open Pit
A41: UG | B41: Underground

Sheet Lutter2025
A1: Region | B1: Mine | C1: (By)products | D1: Mine type | E1: Geology | F1: Process route | G1: New water use [ML] | H1: New water intensity [l/kg] | I1: Share in region | J1: Share in World
A2: Africa | B2: Trident - Sentinel | C2: cunn | D2: Open Pit | E2: seho | F2: concentrator | G2: 66362 | H2: 302 | I2: 0.161 | J2: 0.022
A3: Africa | B3: Kansanshi | C3: cunn | D3: Combined | E3: seho | F3: pyro | G3: 45681 | H3: 197 | I3: 0.111 | J3: 0.015
A4: Africa | B4: Lumwana | C4: cunn | D4: Open Pit | E4: seho | F4: concentrator | G4: 16091 | H4: 149 | I4: 0.039 | J4: 0.005
A5: Africa | B5: Kamoto | C5: cunn | D5: Combined | E5: seho | F5: pyro | G5: 13156 | H5: 49 | I5: 0.032 | J5: 0.004
A6: Africa | B6: Tenke Fungurume | C6: cunn | D6: Open Pit | E6: seho | F6: hydro | G6: 12898 | H6: 72 | I6: 0.031 | J6: 0.004
A7: East Asia | B7: Grasberg | C7: cunn | D7: Combined | E7: pode | F7: concentrator | G7: 44915 | H7: 163 | I7: 0.093 | J7: 0.015
A8: East Asia | B8: Erdenet | C8: cunn | D8: Open Pit | E8: pode | F8: concentrator | G8: 28292 | H8: 192 | I8: 0.059 | J8: 0.01
A9: East Asia | B9: Dexing Complex | C9: cunn | D9: Combined | E9: pode | F9: pyro | G9: 24989 | H9: 162 | I9: 0.052 | J9: 0.008
A10: East Asia | B10: Letpadaung Mountain | C10: cucu | D10: Open Pit | E10: iocg | F10: concentrator | G10: 23843 | H10: 199 | I10: 0.05 | J10: 0.008
A11: East Asia | B11: Batu Hijau | C11: cunn | D11: Open Pit | E11: pode | F11: concentrator | G11: 18433 | H11: 129 | I11: 0.038 | J11: 0.006
A12: Europe & Central Asia | B12: Kola Division | C12: nncu | D12: Combined | E12: na | F12: pyro | G12: 27950 | H12: 321 | I12: 0.076 | J12: 0.009
A13: Europe & Central Asia | B13: Polar Division | C13: nncu | D13: Combined | E13: nnnn | F13: pyro | G13: 26500 | H13: 74 | I13: 0.072 | J13: 0.009
... A16: Europe & Central Asia | B16: Zhezkazgan Complex | C16: cunn | D16: Combined | E16: seho | F16: pyro | G16: 21869 | H16: 142 | I16: 0.06 | J16: 0.007
A17: Latin America & Caribbean | B17: Cobre Panama | C17: cunn | D17: Open Pit | E17: pode | F17: concentrator | G17: 121848 | H17: 826 | I17: 0.104 | J17: 4,1%
A18: Latin America & Caribbean | B18: Escondida | C18: cunn | D18: Open Pit | E18: pode | F18: hydro | G18: 100906 | H18: 85 | I18: 0.086 | J18: 0.034
A19: Latin America & Caribbean | B19: El Teniente | C19: cunn | D19: Combined | E19: pode | F19: pyro | G19: 69575 | H19: 151 | I19: 0.059 | J19: 0.024
A20: Latin America & Caribbean | B20: Chuquicamata | C20: cunn | D20: Open Pit | E20: pode | F20: hydro | G20: 62965 | H20: 163 | I20: 0.054 | J20: 0.021
A21: Latin America & Caribbean | B21: Cerro Verde | C21: cunn | D21: Open Pit | E21: pode | F21: hydro | G21: 53699 | H21: 118 | I21: 0.046 | J21: 0.018
A22: North America | B22: Morenci | C22: cunn | D22: Open Pit | E22: pode | F22: hydro | G22: 53057 | H22: 115 | I22: 0.158 | J22: 0.018
A23: North America | B23: Kennecott | C23: cunn | D23: Combined | E23: pode | F23: pyro | G23: 22962 | H23: 123 | I23: 0.068 | J23: 0.008
A24: North America | B24: Highland Valley | C24: cunn | D24: Open Pit | E24: pode | F24: concentrator | G24: 19588 | H24: 161 | I24: 0.058 | J24: 0.007
A25: North America | B25: Mission | C25: cunn | D25: Combined | E25: pode | F25: concentrator | G25: 18549 | H25: 379 | I25: 0.055 | J25: 0.006
A26: North America | B26: Bagdad | C26: cunn | D26: Open Pit | E26: pode | F26: hydro | G26: 15041 | H26: 152 | I26: 0.045 | J26: 0.005
A27: Oceania | B27: Boddington | C27: nncu | D27: Combined | E27: nnnn | F27: hydro | G27: 21787 | H27: 750 | I27: 0.158 | J27: 0.007
A28: Oceania | B28: Telfer | C28: nncu | D28: Combined | E28: nnnn | F28: hydro | G28: 17744 | H28: 1181 | I28: 0.129 | J28: 0.006
A29: Oceania | B29: Mt Isa Copper | C29: cunn | D29: Combined | E29: seho | F29: pyro | G29: 13433 | H29: 61 | I29: 0.097 | J29: 0.005
... A41: World | B41: Chuquicamata | C41: cunn | D41: Open Pit | E41: pode | F41: hydro | G41: 62965 | H41: 163 | I41: 0.054 | J41: 0.021
A45: Dict
A46: seho | B46: sediment hosted
A47: pode | B47: porphyry deposit
A48: iocg | B48: iron oxide copper-gold deposit
A49: voms | B49: volcanogenic massive sulfide deposit
A50: nnnn | B50: other type of deposit
A51: na | B51: unknown type of deposit
A54: cunn | B54: copper as main product
A55: nncu | B55: copper as by-product

Sheet Pena 2014
A1: Table S5 Statistical variation of total water consumption by the oxide ore refining process.
A2: Region in Chile | B2: Company | C2: Copper Cathode Production in 2005,thousand tonnes/year | D2: Reference | E2: Water Consumed in Cathode Production,m /tonne of dry mineral | F2: Average Ore Grade (mass fraction of copper), unitless | G2: Water Consumed inCopper Cathode Production,m3/tonne of copper cathode
A3: Tarapaca | B3: Cerro Colorado | C3: 104 | D3: Züfiiga 2008 | E3: 0.2 | F3: 0.68 | G3: 43.9
A4: Tarapaca | B4: Quebrada Blanca | C4: 85 | D4: Züfiiga 2008 | E4: 0.13 | F4: 0.9 | G4: 21.6
A5: Tarapaca | B5: Inés de Collahuasi | C5: 58 | D5: Collahuasi 2005 | E5: 0.08 | F5: 0.9 | G5: 13.3
A6: Antofagasta | B6: El Abra | C6: 166 | D6: Züfii a 2008 | E6: 0.11 | F6: 0.47 | G6: 34.9
A7: Antofagasta | B7: Codelco Norte | C7: 108 | D7: Codelco 2005 | E7: 0.17 | F7: 0.8 | G7: 30.4
A8: Antofagasta | B8: S ence | C8: 165 | D8: Züfii a 2008 | E8: 0.13 | F8: 1.4 | G8: 13.9
A9: Antofagasta | B9: El Tesoro | C9: 91 | D9: Züfii a 2008 | E9: 0.26 | F9: 0.9 | G9: 43.1
A10: Antofagasta | B10: Codelco Gabi | C10: 68 | D10: Züfii a 2008 | E10: 0.13 | F10: 0.41 | G10: 47.3
A11: Antofagasta | B11: Zaldivar | C11: 134 | D11: Züfii a 2008 | E11: 0.13 | F11: 0.7 | G11: 27.7
A12: Antofagasta | B12: Escondida | C12: 150 | D12: Escondida 2005 | E12: 0.07 | F12: 1.6 | G12: 6.3
A13: Antofagasta | B13: Mantos Blancos | C13: 48 | D13: A-A 2005 | E13: 0.13 | F13: 0.7 | G13: 26.5
A14: Atacama | B14: Codelco Salvador | C14: 45 | D14: Codelco 2005 | E14: 0.25 | F14: 0.61 | G14: 58.6
A15: Atacama | B15: Manto Verde | C15: 62 | D15: Züfii a 2008 | E15: 0.2 | F15: 0.7 | G15: 42.6
A21: Table S6 Statistical variation of total water consumption m the sulfide ore refining process. Fine copper is the copper in the concentrate after drying.
F22: Average Ore
A23: Region in Chile | B23: Company | C23: Production ofFine Copper in 2005,thousand tonnes /year | D23: Reference | E23: Water Consumed in Concentrate Production,m /tonne of dry mineral | F23: Grade (mass fraction of copper), unitless | G23: Water Consumed in Concentrate Production,m /tonne of fine copper
A24: Tarapaca | B24: Inés de Collahuasi | C24: 423 | D24: Collahuasi 2005 | E24: 0.7 | F24: 0.67 | G24: 104.5
A25: Antofagasta | B25: Codelco Norte | C25: 634 | D25: Codelco 2005 | E25: 0.74 | F25: 1.03 | G25: 71.8
A26: Antofagasta | B26: Escondida | C26: 1070 | D26: Escondida 2005 | E26: 0.71 | F26: 1.64 | G26: 43.3
A27: Antofagasta | B27: Mantos Blancos | C27: 87 | D27: A-A 2005 | E27: 0.63 | F27: 0.7 | G27: 90
A28: Atacama | B28: Codelco Salvador | C28: 39 | D28: Codelco 2005 | E28: 2.07 | F28: 0.67 | G28: 309
A29: Atacama | B29: Minera Candelaria | C29: 174 | D29: Züfiiga 2008 | E29: 0.31 | F29: 0.52 | G29: 59.6
A30: Atacama | B30: Minera Ojos del Salado | C30: 29 | D30: Züfiiga 2008 | E30: 1.9 | F30: 0.7 | G30: 280
A31: Coquimbo | B31: Los Pelambres | C31: 351 | D31: Züfii a 2008 | E31: 0.39 | F31: 0.64 | G31: 60.9
A35: Note: the reference unit is copper content m the concentrate, because not all mining companies have smelting and/or electrorefining plants.
