Workbook

Sheet Metadata

Sheet Analysis
E7: Sum of Grade ore Li%
E8: Type | F8: DLE | G8: Deposit | H8: Ref_Water2 | I8: Total
E9: Brine | F9: No | G9: Atacama | H9: Feng et al. (2025) | I9: 0.00083
H10: Lagos et al. (2024) | I10: 0.0019
H11: Schenker & Pfister (2025) | I11: 0.0015
H12: Sun et al. (2024) | I12: 0.0015
H13: Vera et al. (2023) | I13: 0.00157
G14: Brine high grade | H14: Mas-Fons et al. (2024) | I14: 0.001048
G15: Brine low grade | H15: Mas-Fons et al. (2024) | I15: 3.8e-05
G16: Brine medium grade | H16: Mas-Fons et al. (2024) | I16: 0.000347
G17: Cauchari-Olaroz | H17: Feng et al. (2025) | I17: 0.00083
H18: Schenker & Pfister (2025) | I18: 0.0005
G19: Dongtai Jinaier | H19: Sun et al. (2024) | I19: 0.0002
G20: Fenix | H20: Paz et al. (2025) | I20: 0.000523
G21: Hombre Muerto | H21: Sun et al. (2024) | I21: 0.0007
G22: Hombre Muerto North | H22: Schenker & Pfister (2025) | I22: 0.0007
G23: Maricunga | H23: Schenker & Pfister (2025) | I23: 0.0009
G24: Olaroz | H24: Feng et al. (2025) | I24: 0.00083
H25: Paz et al. (2025) | I25: 0.00063
H26: Schenker & Pfister (2025) | I26: 0.0006
H27: Sun et al. (2024) | I27: 0.0005
G28: Pastos Grandes | H28: Schenker & Pfister (2025) | I28: 0.0004
G29: Qarhan | H29: Sun et al. (2024) | I29: 0.0002
G30: Sal de Vida | H30: Schenker & Pfister (2025) | I30: 0.0008
G31: Silver Peak | H31: Feng et al. (2025) | I31: 0.00083
H32: Schenker & Pfister (2025) | I32: 0.0002
H33: Sun et al. (2024) | I33: 0.0003
G34: Tres Quebradas | H34: Schenker & Pfister (2025) | I34: 0.001
G35: West Tajinar | H35: Feng et al. (2025) | I35: 0.00021
G36: Xitai Jinaier | H36: Sun et al. (2024) | I36: 0.0002
G37: Zabuye | H37: Sun et al. (2024) | I37: 0.00097
G38: Chile | H38: Orquera et al. (2026)
G39: Argentina | H39: Orquera et al. (2026)
G40: Bolivia | H40: Orquera et al. (2026)
G41: Salar de Olaroz | H41: Vera et al. (2023) | I41: 0.00057
F42: Yes | G42: Antofalla | H42: Schenker & Pfister (2025) | I42: 0.0003
G43: Arizaro | H43: Schenker & Pfister (2025) | I43: 0.0003
G44: Atacama | H44: Vera et al. (2023) | I44: 0.00157
G45: Barunma Sea | H45: Feng et al. (2025) | I45: 0.000155
G46: Centenario | H46: Schenker & Pfister (2025) | I46: 0.0003
...

Sheet Database
A1: Order | B1: Include | C1: Reason_Exclusion | D1: Deposit | E1: Name | F1: ID | G1: Type | H1: Grade ore Li% | I1: Ref_grade | J1: Brine Water | K1: Freshwater | L1: Total Water | M1: Unit num | N1: Unit den | O1: DLE | P1: Detail | Q1: Water type | R1: Ref_Water | S1: Ref_Water2 | T1: BrineWater_m3_tonLCE | U1: FreshWater_m3_tonLCE | V1: TotalWater_m3_tonLCE | W1: Brine_m3_tonLCE_GradeOnly | X1: Implied_Recovery
A2: 1 | B2: 1 | D2: Atacama | E2: Salar de Atacama (SQM) | F2: 37384 | G2: Brine | H2: 0.0015 | I2: 3 | K2: 47 | L2: =+Table2[[#This Row],[Brine Water]]+Table2[[#This Row],[Freshwater]] -> 47 | M2: kg | N2: kg LCE Battery grade | O2: No | P2: Conventional chemical-based technology | Q2: Freshwater consumption | R2: 3 | S2: =+VLOOKUP(R2,Refs[],2,0) -> Schenker & Pfister (2025) | T2: =IF(ISBLANK(Table2[[#This Row],[Brine Water]]),"",+VLOOKUP(Table2[[#This Row],[Unit num]]&"/"&Table2[[#This Row],[Unit den]],Conversion!$A$2:$B$50,2,0)*Table2[[#This Row],[Brine Water]]) | U2: =IF(ISBLANK(Table2[[#This Row],[Freshwater]]),"",+VLOOKUP(Table2[[#This Row],[Unit num]]&"/"&Table2[[#This Row],[Unit den]],Conversion!$A$2:$B$50,2,0)*Table2[[#This Row],[Freshwater]]) -> 47 | V2: =+VLOOKUP(Table2[[#This Row],[Unit num]]&"/"&Table2[[#This Row],[Unit den]],Conversion!$A$2:$B$50,2,0)*Table2[[#This Row],[Total Water]] -> 47 | W2: =IF(ISNUMBER(FIND("Brine",Table2[[#This Row],[Type]])),1/Table2[[#This Row],[Grade ore Li%]]/5.323,"") -> 125.24266 | X2: =+IF(ISBLANK(Table2[[#This Row],[Brine Water]]),"",Table2[[#This Row],[Brine_m3_tonLCE_GradeOnly]]/Table2[[#This Row],[BrineWater_m3_tonLCE]])
A3: 2 | B3: 1 | D3: Tres Quebradas | E3: Tres Quebradas | F3: 78031 | G3: Brine | H3: 0.001 | I3: 3 | K3: 53 | L3: =+Table2[[#This Row],[Brine Water]]+Table2[[#This Row],[Freshwater]] -> 53 | M3: kg | N3: kg LCE Battery grade | O3: No | P3: Conventional chemical-based technology | Q3: Freshwater consumption | R3: 3 | S3: =+VLOOKUP(R3,Refs[],2,0) -> Schenker & Pfister (2025) | T3: =IF(ISBLANK(Table2[[#This Row],[Brine Water]]),"",+VLOOKUP(Table2[[#This Row],[Unit num]]&"/"&Table2[[#This Row],[Unit den]],Conversion!$A$2:$B$50,2,0)*Table2[[#This Row],[Brine Water]]) | U3: =IF(ISBLANK(Table2[[#This Row],[Freshwater]]),"",+VLOOKUP(Table2[[#This Row],[Unit num]]&"/"&Table2[[#This Row],[Unit den]],Conversion!$A$2:$B$50,2,0)*Table2[[#This Row],[Freshwater]]) -> 53 | V3: =+VLOOKUP(Table2[[#This Row],[Unit num]]&"/"&Table2[[#This Row],[Unit den]],Conversion!$A$2:$B$50,2,0)*Table2[[#This Row],[Total Water]] -> 53 | W3: =IF(ISNUMBER(FIND("Brine",Table2[[#This Row],[Type]])),1/Table2[[#This Row],[Grade ore Li%]]/5.323,"") -> 187.86399 | X3: =+IF(ISBLANK(Table2[[#This Row],[Brine Water]]),"",Table2[[#This Row],[Brine_m3_tonLCE_GradeOnly]]/Table2[[#This Row],[BrineWater_m3_tonLCE]])
A4: 3 | B4: 1 | D4: Maricunga | E4: Salar de Maricunga | F4: 38700 | G4: Brine | H4: 0.0009 | I4: 3 | K4: 200 | L4: =+Table2[[#This Row],[Brine Water]]+Table2[[#This Row],[Freshwater]] -> 200 | M4: kg | N4: kg LCE Battery grade | O4: No | P4: Conventional chemical-based technology | Q4: Freshwater consumption | R4: 3 | S4: =+VLOOKUP(R4,Refs[],2,0) -> Schenker & Pfister (2025) | T4: =IF(ISBLANK(Table2[[#This Row],[Brine Water]]),"",+VLOOKUP(Table2[[#This Row],[Unit num]]&"/"&Table2[[#This Row],[Unit den]],Conversion!$A$2:$B$50,2,0)*Table2[[#This Row],[Brine Water]]) | U4: =IF(ISBLANK(Table2[[#This Row],[Freshwater]]),"",+VLOOKUP(Table2[[#This Row],[Unit num]]&"/"&Table2[[#This Row],[Unit den]],Conversion!$A$2:$B$50,2,0)*Table2[[#This Row],[Freshwater]]) -> 200 | V4: =+VLOOKUP(Table2[[#This Row],[Unit num]]&"/"&Table2[[#This Row],[Unit den]],Conversion!$A$2:$B$50,2,0)*Table2[[#This Row],[Total Water]] -> 200 | W4: =IF(ISNUMBER(FIND("Brine",Table2[[#This Row],[Type]])),1/Table2[[#This Row],[Grade ore Li%]]/5.323,"") -> 208.73776 | X4: =+IF(ISBLANK(Table2[[#This Row],[Brine Water]]),"",Table2[[#This Row],[Brine_m3_tonLCE_GradeOnly]]/Table2[[#This Row],[BrineWater_m3_tonLCE]])
A5: 4 | B5: 1 | D5: Sal de Vida | E5: Sal de Vida | F5: 37611 | G5: Brine | H5: 0.0008 | I5: 3 | K5: 33 | L5: =+Table2[[#This Row],[Brine Water]]+Table2[[#This Row],[Freshwater]] -> 33 | M5: kg | N5: kg LCE Battery grade | O5: No | P5: Conventional chemical-based technology | Q5: Freshwater consumption | R5: 3 | S5: =+VLOOKUP(R5,Refs[],2,0) -> Schenker & Pfister (2025) | T5: =IF(ISBLANK(Table2[[#This Row],[Brine Water]]),"",+VLOOKUP(Table2[[#This Row],[Unit num]]&"/"&Table2[[#This Row],[Unit den]],Conversion!$A$2:$B$50,2,0)*Table2[[#This Row],[Brine Water]]) | U5: =IF(ISBLANK(Table2[[#This Row],[Freshwater]]),"",+VLOOKUP(Table2[[#This Row],[Unit num]]&"/"&Table2[[#This Row],[Unit den]],Conversion!$A$2:$B$50,2,0)*Table2[[#This Row],[Freshwater]]) -> 33 | V5: =+VLOOKUP(Table2[[#This Row],[Unit num]]&"/"&Table2[[#This Row],[Unit den]],Conversion!$A$2:$B$50,2,0)*Table2[[#This Row],[Total Water]] -> 33 | W5: =IF(ISNUMBER(FIND("Brine",Table2[[#This Row],[Type]])),1/Table2[[#This Row],[Grade ore Li%]]/5.323,"") -> 234.82998 | X5: =+IF(ISBLANK(Table2[[#This Row],[Brine Water]]),"",Table2[[#This Row],[Brine_m3_tonLCE_GradeOnly]]/Table2[[#This Row],[BrineWater_m3_tonLCE]])
A6: 5 | B6: 1 | D6: Hombre Muerto North | E6: Hombre Muerto North (Lithium South) | F6: 79236 | G6: Brine | H6: 0.0007 | I6: 3 | K6: 61 | L6: =+Table2[[#This Row],[Brine Water]]+Table2[[#This Row],[Freshwater]] -> 61 | M6: kg | N6: kg LCE Battery grade | O6: No | P6: Conventional chemical-based technology | Q6: Freshwater consumption | R6: 3 | S6: =+VLOOKUP(R6,Refs[],2,0) -> Schenker & Pfister (2025) | T6: =IF(ISBLANK(Table2[[#This Row],[Brine Water]]),"",+VLOOKUP(Table2[[#This Row],[Unit num]]&"/"&Table2[[#This Row],[Unit den]],Conversion!$A$2:$B$50,2,0)*Table2[[#This Row],[Brine Water]]) | U6: =IF(ISBLANK(Table2[[#This Row],[Freshwater]]),"",+VLOOKUP(Table2[[#This Row],[Unit num]]&"/"&Table2[[#This Row],[Unit den]],Conversion!$A$2:$B$50,2,0)*Table2[[#This Row],[Freshwater]]) -> 61 | V6: =+VLOOKUP(Table2[[#This Row],[Unit num]]&"/"&Table2[[#This Row],[Unit den]],Conversion!$A$2:$B$50,2,0)*Table2[[#This Row],[Total Water]] -> 61 | W6: =IF(ISNUMBER(FIND("Brine",Table2[[#This Row],[Type]])),1/Table2[[#This Row],[Grade ore Li%]]/5.323,"") -> 268.37712 | X6: =+IF(ISBLANK(Table2[[#This Row],[Brine Water]]),"",Table2[[#This Row],[Brine_m3_tonLCE_GradeOnly]]/Table2[[#This Row],[BrineWater_m3_tonLCE]])
A7: 6 | B7: 1 | D7: Cauchari-Olaroz | E7: #N/A | F7: 37624 | G7: Brine | H7: 0.0005 | I7: 3 | K7: 56 | L7: =+Table2[[#This Row],[Brine Water]]+Table2[[#This Row],[Freshwater]] -> 56 | M7: kg | N7: kg LCE Battery grade | O7: No | P7: Conventional chemical-based technology | Q7: Freshwater consumption | R7: 3 | S7: =+VLOOKUP(R7,Refs[],2,0) -> Schenker & Pfister (2025) | T7: =IF(ISBLANK(Table2[[#This Row],[Brine Water]]),"",+VLOOKUP(Table2[[#This Row],[Unit num]]&"/"&Table2[[#This Row],[Unit den]],Conversion!$A$2:$B$50,2,0)*Table2[[#This Row],[Brine Water]]) | U7: =IF(ISBLANK(Table2[[#This Row],[Freshwater]]),"",+VLOOKUP(Table2[[#This Row],[Unit num]]&"/"&Table2[[#This Row],[Unit den]],Conversion!$A$2:$B$50,2,0)*Table2[[#This Row],[Freshwater]]) -> 56 | V7: =+VLOOKUP(Table2[[#This Row],[Unit num]]&"/"&Table2[[#This Row],[Unit den]],Conversion!$A$2:$B$50,2,0)*Table2[[#This Row],[Total Water]] -> 56 | W7: =IF(ISNUMBER(FIND("Brine",Table2[[#This Row],[Type]])),1/Table2[[#This Row],[Grade ore Li%]]/5.323,"") -> 375.72797 | X7: =+IF(ISBLANK(Table2[[#This Row],[Brine Water]]),"",Table2[[#This Row],[Brine_m3_tonLCE_GradeOnly]]/Table2[[#This Row],[BrineWater_m3_tonLCE]])
A8: 7 | B8: 1 | D8: Pastos Grandes | E8: Pastos Grandes (Lithium Americas) | F8: 77807 | G8: Brine | H8: 0.0004 | I8: 3 | K8: 85 | L8: =+Table2[[#This Row],[Brine Water]]+Table2[[#This Row],[Freshwater]] -> 85 | M8: kg | N8: kg LCE Battery grade | O8: No | P8: Conventional chemical-based technology | Q8: Freshwater consumption | R8: 3 | S8: =+VLOOKUP(R8,Refs[],2,0) -> Schenker & Pfister (2025) | T8: =IF(ISBLANK(Table2[[#This Row],[Brine Water]]),"",+VLOOKUP(Table2[[#This Row],[Unit num]]&"/"&Table2[[#This Row],[Unit den]],Conversion!$A$2:$B$50,2,0)*Table2[[#This Row],[Brine Water]]) | U8: =IF(ISBLANK(Table2[[#This Row],[Freshwater]]),"",+VLOOKUP(Table2[[#This Row],[Unit num]]&"/"&Table2[[#This Row],[Unit den]],Conversion!$A$2:$B$50,2,0)*Table2[[#This Row],[Freshwater]]) -> 85 | V8: =+VLOOKUP(Table2[[#This Row],[Unit num]]&"/"&Table2[[#This Row],[Unit den]],Conversion!$A$2:$B$50,2,0)*Table2[[#This Row],[Total Water]] -> 85 | W8: =IF(ISNUMBER(FIND("Brine",Table2[[#This Row],[Type]])),1/Table2[[#This Row],[Grade ore Li%]]/5.323,"") -> 469.65997 | X8: =+IF(ISBLANK(Table2[[#This Row],[Brine Water]]),"",Table2[[#This Row],[Brine_m3_tonLCE_GradeOnly]]/Table2[[#This Row],[BrineWater_m3_tonLCE]])
A9: 8 | B9: 1 | D9: Olaroz | E9: Salar de Olaroz (Allkem) | F9: 37059 | G9: Brine | H9: 0.0006 | I9: 3 | K9: 128 | L9: =+Table2[[#This Row],[Brine Water]]+Table2[[#This Row],[Freshwater]] -> 128 | M9: kg | N9: kg LCE Battery grade | O9: No | P9: conventional ion exchanger technology | Q9: Freshwater consumption | R9: 3 | S9: =+VLOOKUP(R9,Refs[],2,0) -> Schenker & Pfister (2025) | T9: =IF(ISBLANK(Table2[[#This Row],[Brine Water]]),"",+VLOOKUP(Table2[[#This Row],[Unit num]]&"/"&Table2[[#This Row],[Unit den]],Conversion!$A$2:$B$50,2,0)*Table2[[#This Row],[Brine Water]]) | U9: =IF(ISBLANK(Table2[[#This Row],[Freshwater]]),"",+VLOOKUP(Table2[[#This Row],[Unit num]]&"/"&Table2[[#This Row],[Unit den]],Conversion!$A$2:$B$50,2,0)*Table2[[#This Row],[Freshwater]]) -> 128 | V9: =+VLOOKUP(Table2[[#This Row],[Unit num]]&"/"&Table2[[#This Row],[Unit den]],Conversion!$A$2:$B$50,2,0)*Table2[[#This Row],[Total Water]] -> 128 | W9: =IF(ISNUMBER(FIND("Brine",Table2[[#This Row],[Type]])),1/Table2[[#This Row],[Grade ore Li%]]/5.323,"") -> 313.10664 | X9: =+IF(ISBLANK(Table2[[#This Row],[Brine Water]]),"",Table2[[#This Row],[Brine_m3_tonLCE_GradeOnly]]/Table2[[#This Row],[BrineWater_m3_tonLCE]])
A10: 9 | B10: 1 | D10: Silver Peak | E10: Silver Peak | F10: 37600 | G10: Brine | H10: 0.0002 | I10: 3 | K10: 67 | L10: =+Table2[[#This Row],[Brine Water]]+Table2[[#This Row],[Freshwater]] -> 67 | M10: kg | N10: kg LCE Battery grade | O10: No | P10: conventional ion exchanger technology | Q10: Freshwater consumption | R10: 3 | S10: =+VLOOKUP(R10,Refs[],2,0) -> Schenker & Pfister (2025) | T10: =IF(ISBLANK(Table2[[#This Row],[Brine Water]]),"",+VLOOKUP(Table2[[#This Row],[Unit num]]&"/"&Table2[[#This Row],[Unit den]],Conversion!$A$2:$B$50,2,0)*Table2[[#This Row],[Brine Water]]) | U10: =IF(ISBLANK(Table2[[#This Row],[Freshwater]]),"",+VLOOKUP(Table2[[#This Row],[Unit num]]&"/"&Table2[[#This Row],[Unit den]],Conversion!$A$2:$B$50,2,0)*Table2[[#This Row],[Freshwater]]) -> 67 | V10: =+VLOOKUP(Table2[[#This Row],[Unit num]]&"/"&Table2[[#This Row],[Unit den]],Conversion!$A$2:$B$50,2,0)*Table2[[#This Row],[Total Water]] -> 67 | W10: =IF(ISNUMBER(FIND("Brine",Table2[[#This Row],[Type]])),1/Table2[[#This Row],[Grade ore Li%]]/5.323,"") -> 939.31993 | X10: =+IF(ISBLANK(Table2[[#This Row],[Brine Water]]),"",Table2[[#This Row],[Brine_m3_tonLCE_GradeOnly]]/Table2[[#This Row],[BrineWater_m3_tonLCE]])
A11: 10 | B11: 1 | D11: Uyuni | E11: Salar de Uyuni | F11: 36153 | G11: Brine | H11: 0.0007 | I11: 3 | K11: 336 | L11: =+Table2[[#This Row],[Brine Water]]+Table2[[#This Row],[Freshwater]] -> 336 | M11: kg | N11: kg LCE Battery grade | O11: Yes | P11: DLE technology from continental brines | Q11: Freshwater consumption | R11: 3 | S11: =+VLOOKUP(R11,Refs[],2,0) -> Schenker & Pfister (2025) | T11: =IF(ISBLANK(Table2[[#This Row],[Brine Water]]),"",+VLOOKUP(Table2[[#This Row],[Unit num]]&"/"&Table2[[#This Row],[Unit den]],Conversion!$A$2:$B$50,2,0)*Table2[[#This Row],[Brine Water]]) | U11: =IF(ISBLANK(Table2[[#This Row],[Freshwater]]),"",+VLOOKUP(Table2[[#This Row],[Unit num]]&"/"&Table2[[#This Row],[Unit den]],Conversion!$A$2:$B$50,2,0)*Table2[[#This Row],[Freshwater]]) -> 336 | V11: =+VLOOKUP(Table2[[#This Row],[Unit num]]&"/"&Table2[[#This Row],[Unit den]],Conversion!$A$2:$B$50,2,0)*Table2[[#This Row],[Total Water]] -> 336 | W11: =IF(ISNUMBER(FIND("Brine",Table2[[#This Row],[Type]])),1/Table2[[#This Row],[Grade ore Li%]]/5.323,"") -> 268.37712 | X11: =+IF(ISBLANK(Table2[[#This Row],[Brine Water]]),"",Table2[[#This Row],[Brine_m3_tonLCE_GradeOnly]]/Table2[[#This Row],[BrineWater_m3_tonLCE]])
A12: 11 | B12: 1 | D12: Fenix | E12: Salar del Hombre Muerto (Livent) | F12: 37611 | G12: Brine | H12: 0.0007 | I12: 3 | K12: 247 | L12: =+Table2[[#This Row],[Brine Water]]+Table2[[#This Row],[Freshwater]] -> 247 | M12: kg | N12: kg LCE Battery grade | O12: Yes | P12: DLE technology from continental brines | Q12: Freshwater consumption | R12: 3 | S12: =+VLOOKUP(R12,Refs[],2,0) -> Schenker & Pfister (2025) | T12: =IF(ISBLANK(Table2[[#This Row],[Brine Water]]),"",+VLOOKUP(Table2[[#This Row],[Unit num]]&"/"&Table2[[#This Row],[Unit den]],Conversion!$A$2:$B$50,2,0)*Table2[[#This Row],[Brine Water]]) | U12: =IF(ISBLANK(Table2[[#This Row],[Freshwater]]),"",+VLOOKUP(Table2[[#This Row],[Unit num]]&"/"&Table2[[#This Row],[Unit den]],Conversion!$A$2:$B$50,2,0)*Table2[[#This Row],[Freshwater]]) -> 247 | V12: =+VLOOKUP(Table2[[#This Row],[Unit num]]&"/"&Table2[[#This Row],[Unit den]],Conversion!$A$2:$B$50,2,0)*Table2[[#This Row],[Total Water]] -> 247 | W12: =IF(ISNUMBER(FIND("Brine",Table2[[#This Row],[Type]])),1/Table2[[#This Row],[Grade ore Li%]]/5.323,"") -> 268.37712 | X12: =+IF(ISBLANK(Table2[[#This Row],[Brine Water]]),"",Table2[[#This Row],[Brine_m3_tonLCE_GradeOnly]]/Table2[[#This Row],[BrineWater_m3_tonLCE]])
A13: 12 | B13: 1 | D13: Rio Grande | E13: #N/A | F13: 80111 | G13: Brine | H13: 0.0003 | I13: 3 | K13: 261 | L13: =+Table2[[#This Row],[Brine Water]]+Table2[[#This Row],[Freshwater]] -> 261 | M13: kg | N13: kg LCE Battery grade | O13: Yes | P13: DLE technology from continental brines | Q13: Freshwater consumption | R13: 3 | S13: =+VLOOKUP(R13,Refs[],2,0) -> Schenker & Pfister (2025) | T13: =IF(ISBLANK(Table2[[#This Row],[Brine Water]]),"",+VLOOKUP(Table2[[#This Row],[Unit num]]&"/"&Table2[[#This Row],[Unit den]],Conversion!$A$2:$B$50,2,0)*Table2[[#This Row],[Brine Water]]) | U13: =IF(ISBLANK(Table2[[#This Row],[Freshwater]]),"",+VLOOKUP(Table2[[#This Row],[Unit num]]&"/"&Table2[[#This Row],[Unit den]],Conversion!$A$2:$B$50,2,0)*Table2[[#This Row],[Freshwater]]) -> 261 | V13: =+VLOOKUP(Table2[[#This Row],[Unit num]]&"/"&Table2[[#This Row],[Unit den]],Conversion!$A$2:$B$50,2,0)*Table2[[#This Row],[Total Water]] -> 261 | W13: =IF(ISNUMBER(FIND("Brine",Table2[[#This Row],[Type]])),1/Table2[[#This Row],[Grade ore Li%]]/5.323,"") -> 626.21329 | X13: =+IF(ISBLANK(Table2[[#This Row],[Brine Water]]),"",Table2[[#This Row],[Brine_m3_tonLCE_GradeOnly]]/Table2[[#This Row],[BrineWater_m3_tonLCE]])
A14: 13 | B14: 1 | D14: Centenario | E14: Centenario Ratones | F14: 52372 | G14: Brine | H14: 0.0003 | I14: 3 | K14: 265 | L14: =+Table2[[#This Row],[Brine Water]]+Table2[[#This Row],[Freshwater]] -> 265 | M14: kg | N14: kg LCE Battery grade | O14: Yes | P14: DLE technology from continental brines | Q14: Freshwater consumption | R14: 3 | S14: =+VLOOKUP(R14,Refs[],2,0) -> Schenker & Pfister (2025) | T14: =IF(ISBLANK(Table2[[#This Row],[Brine Water]]),"",+VLOOKUP(Table2[[#This Row],[Unit num]]&"/"&Table2[[#This Row],[Unit den]],Conversion!$A$2:$B$50,2,0)*Table2[[#This Row],[Brine Water]]) | U14: =IF(ISBLANK(Table2[[#This Row],[Freshwater]]),"",+VLOOKUP(Table2[[#This Row],[Unit num]]&"/"&Table2[[#This Row],[Unit den]],Conversion!$A$2:$B$50,2,0)*Table2[[#This Row],[Freshwater]]) -> 265 | V14: =+VLOOKUP(Table2[[#This Row],[Unit num]]&"/"&Table2[[#This Row],[Unit den]],Conversion!$A$2:$B$50,2,0)*Table2[[#This Row],[Total Water]] -> 265 | W14: =IF(ISNUMBER(FIND("Brine",Table2[[#This Row],[Type]])),1/Table2[[#This Row],[Grade ore Li%]]/5.323,"") -> 626.21329 | X14: =+IF(ISBLANK(Table2[[#This Row],[Brine Water]]),"",Table2[[#This Row],[Brine_m3_tonLCE_GradeOnly]]/Table2[[#This Row],[BrineWater_m3_tonLCE]])
A15: 14 | B15: 1 | D15: Rincon | E15: Salar del Rincon (Rio Tinto) | F15: 78109 | G15: Brine | H15: 0.0003 | I15: 3 | K15: 269 | L15: =+Table2[[#This Row],[Brine Water]]+Table2[[#This Row],[Freshwater]] -> 269 | M15: kg | N15: kg LCE Battery grade | O15: Yes | P15: DLE technology from continental brines | Q15: Freshwater consumption | R15: 3 | S15: =+VLOOKUP(R15,Refs[],2,0) -> Schenker & Pfister (2025) | T15: =IF(ISBLANK(Table2[[#This Row],[Brine Water]]),"",+VLOOKUP(Table2[[#This Row],[Unit num]]&"/"&Table2[[#This Row],[Unit den]],Conversion!$A$2:$B$50,2,0)*Table2[[#This Row],[Brine Water]]) | U15: =IF(ISBLANK(Table2[[#This Row],[Freshwater]]),"",+VLOOKUP(Table2[[#This Row],[Unit num]]&"/"&Table2[[#This Row],[Unit den]],Conversion!$A$2:$B$50,2,0)*Table2[[#This Row],[Freshwater]]) -> 269 | V15: =+VLOOKUP(Table2[[#This Row],[Unit num]]&"/"&Table2[[#This Row],[Unit den]],Conversion!$A$2:$B$50,2,0)*Table2[[#This Row],[Total Water]] -> 269 | W15: =IF(ISNUMBER(FIND("Brine",Table2[[#This Row],[Type]])),1/Table2[[#This Row],[Grade ore Li%]]/5.323,"") -> 626.21329 | X15: =+IF(ISBLANK(Table2[[#This Row],[Brine Water]]),"",Table2[[#This Row],[Brine_m3_tonLCE_GradeOnly]]/Table2[[#This Row],[BrineWater_m3_tonLCE]])
A16: 15 | B16: 1 | D16: Tolillar | E16: #N/A | F16: 84909 | G16: Brine | H16: 0.0003 | I16: 3 | K16: 269 | L16: =+Table2[[#This Row],[Brine Water]]+Table2[[#This Row],[Freshwater]] -> 269 | M16: kg | N16: kg LCE Battery grade | O16: Yes | P16: DLE technology from continental brines | Q16: Freshwater consumption | R16: 3 | S16: =+VLOOKUP(R16,Refs[],2,0) -> Schenker & Pfister (2025) | T16: =IF(ISBLANK(Table2[[#This Row],[Brine Water]]),"",+VLOOKUP(Table2[[#This Row],[Unit num]]&"/"&Table2[[#This Row],[Unit den]],Conversion!$A$2:$B$50,2,0)*Table2[[#This Row],[Brine Water]]) | U16: =IF(ISBLANK(Table2[[#This Row],[Freshwater]]),"",+VLOOKUP(Table2[[#This Row],[Unit num]]&"/"&Table2[[#This Row],[Unit den]],Conversion!$A$2:$B$50,2,0)*Table2[[#This Row],[Freshwater]]) -> 269 | V16: =+VLOOKUP(Table2[[#This Row],[Unit num]]&"/"&Table2[[#This Row],[Unit den]],Conversion!$A$2:$B$50,2,0)*Table2[[#This Row],[Total Water]] -> 269 | W16: =IF(ISNUMBER(FIND("Brine",Table2[[#This Row],[Type]])),1/Table2[[#This Row],[Grade ore Li%]]/5.323,"") -> 626.21329 | X16: =+IF(ISBLANK(Table2[[#This Row],[Brine Water]]),"",Table2[[#This Row],[Brine_m3_tonLCE_GradeOnly]]/Table2[[#This Row],[BrineWater_m3_tonLCE]])
A17: 16 | B17: 1 | D17: Arizaro | E17: Arizaro | F17: 60483 | G17: Brine | H17: 0.0003 | I17: 3 | K17: 324 | L17: =+Table2[[#This Row],[Brine Water]]+Table2[[#This Row],[Freshwater]] -> 324 | M17: kg | N17: kg LCE Battery grade | O17: Yes | P17: DLE technology from continental brines | Q17: Freshwater consumption | R17: 3 | S17: =+VLOOKUP(R17,Refs[],2,0) -> Schenker & Pfister (2025) | T17: =IF(ISBLANK(Table2[[#This Row],[Brine Water]]),"",+VLOOKUP(Table2[[#This Row],[Unit num]]&"/"&Table2[[#This Row],[Unit den]],Conversion!$A$2:$B$50,2,0)*Table2[[#This Row],[Brine Water]]) | U17: =IF(ISBLANK(Table2[[#This Row],[Freshwater]]),"",+VLOOKUP(Table2[[#This Row],[Unit num]]&"/"&Table2[[#This Row],[Unit den]],Conversion!$A$2:$B$50,2,0)*Table2[[#This Row],[Freshwater]]) -> 324 | V17: =+VLOOKUP(Table2[[#This Row],[Unit num]]&"/"&Table2[[#This Row],[Unit den]],Conversion!$A$2:$B$50,2,0)*Table2[[#This Row],[Total Water]] -> 324 | W17: =IF(ISNUMBER(FIND("Brine",Table2[[#This Row],[Type]])),1/Table2[[#This Row],[Grade ore Li%]]/5.323,"") -> 626.21329 | X17: =+IF(ISBLANK(Table2[[#This Row],[Brine Water]]),"",Table2[[#This Row],[Brine_m3_tonLCE_GradeOnly]]/Table2[[#This Row],[BrineWater_m3_tonLCE]])
A18: 17 | B18: 1 | D18: Antofalla | E18: #N/A | F18: 92966 | G18: Brine | H18: 0.0003 | I18: 3 | K18: 252 | L18: =+Table2[[#This Row],[Brine Water]]+Table2[[#This Row],[Freshwater]] -> 252 | M18: kg | N18: kg LCE Battery grade | O18: Yes | P18: DLE technology from continental brines | Q18: Freshwater consumption | R18: 3 | S18: =+VLOOKUP(R18,Refs[],2,0) -> Schenker & Pfister (2025) | T18: =IF(ISBLANK(Table2[[#This Row],[Brine Water]]),"",+VLOOKUP(Table2[[#This Row],[Unit num]]&"/"&Table2[[#This Row],[Unit den]],Conversion!$A$2:$B$50,2,0)*Table2[[#This Row],[Brine Water]]) | U18: =IF(ISBLANK(Table2[[#This Row],[Freshwater]]),"",+VLOOKUP(Table2[[#This Row],[Unit num]]&"/"&Table2[[#This Row],[Unit den]],Conversion!$A$2:$B$50,2,0)*Table2[[#This Row],[Freshwater]]) -> 252 | V18: =+VLOOKUP(Table2[[#This Row],[Unit num]]&"/"&Table2[[#This Row],[Unit den]],Conversion!$A$2:$B$50,2,0)*Table2[[#This Row],[Total Water]] -> 252 | W18: =IF(ISNUMBER(FIND("Brine",Table2[[#This Row],[Type]])),1/Table2[[#This Row],[Grade ore Li%]]/5.323,"") -> 626.21329 | X18: =+IF(ISBLANK(Table2[[#This Row],[Brine Water]]),"",Table2[[#This Row],[Brine_m3_tonLCE_GradeOnly]]/Table2[[#This Row],[BrineWater_m3_tonLCE]])
A19: 18 | B19: 1 | D19: Salinas Grandes | E19: #N/A | F19: 38323 | G19: Brine | H19: 0.0002 | I19: 3 | K19: 272 | L19: =+Table2[[#This Row],[Brine Water]]+Table2[[#This Row],[Freshwater]] -> 272 | M19: kg | N19: kg LCE Battery grade | O19: Yes | P19: DLE technology from continental brines | Q19: Freshwater consumption | R19: 3 | S19: =+VLOOKUP(R19,Refs[],2,0) -> Schenker & Pfister (2025) | T19: =IF(ISBLANK(Table2[[#This Row],[Brine Water]]),"",+VLOOKUP(Table2[[#This Row],[Unit num]]&"/"&Table2[[#This Row],[Unit den]],Conversion!$A$2:$B$50,2,0)*Table2[[#This Row],[Brine Water]]) | U19: =IF(ISBLANK(Table2[[#This Row],[Freshwater]]),"",+VLOOKUP(Table2[[#This Row],[Unit num]]&"/"&Table2[[#This Row],[Unit den]],Conversion!$A$2:$B$50,2,0)*Table2[[#This Row],[Freshwater]]) -> 272 | V19: =+VLOOKUP(Table2[[#This Row],[Unit num]]&"/"&Table2[[#This Row],[Unit den]],Conversion!$A$2:$B$50,2,0)*Table2[[#This Row],[Total Water]] -> 272 | W19: =IF(ISNUMBER(FIND("Brine",Table2[[#This Row],[Type]])),1/Table2[[#This Row],[Grade ore Li%]]/5.323,"") -> 939.31993 | X19: =+IF(ISBLANK(Table2[[#This Row],[Brine Water]]),"",Table2[[#This Row],[Brine_m3_tonLCE_GradeOnly]]/Table2[[#This Row],[BrineWater_m3_tonLCE]])
A20: 19 | B20: 1 | D20: Kachi | E20: Kachi | F20: 78657 | G20: Brine | H20: 0.0002 | I20: 3 | K20: 304 | L20: =+Table2[[#This Row],[Brine Water]]+Table2[[#This Row],[Freshwater]] -> 304 | M20: kg | N20: kg LCE Battery grade | O20: Yes | P20: DLE technology from continental brines | Q20: Freshwater consumption | R20: 3 | S20: =+VLOOKUP(R20,Refs[],2,0) -> Schenker & Pfister (2025) | T20: =IF(ISBLANK(Table2[[#This Row],[Brine Water]]),"",+VLOOKUP(Table2[[#This Row],[Unit num]]&"/"&Table2[[#This Row],[Unit den]],Conversion!$A$2:$B$50,2,0)*Table2[[#This Row],[Brine Water]]) | U20: =IF(ISBLANK(Table2[[#This Row],[Freshwater]]),"",+VLOOKUP(Table2[[#This Row],[Unit num]]&"/"&Table2[[#This Row],[Unit den]],Conversion!$A$2:$B$50,2,0)*Table2[[#This Row],[Freshwater]]) -> 304 | V20: =+VLOOKUP(Table2[[#This Row],[Unit num]]&"/"&Table2[[#This Row],[Unit den]],Conversion!$A$2:$B$50,2,0)*Table2[[#This Row],[Total Water]] -> 304 | W20: =IF(ISNUMBER(FIND("Brine",Table2[[#This Row],[Type]])),1/Table2[[#This Row],[Grade ore Li%]]/5.323,"") -> 939.31993 | X20: =+IF(ISBLANK(Table2[[#This Row],[Brine Water]]),"",Table2[[#This Row],[Brine_m3_tonLCE_GradeOnly]]/Table2[[#This Row],[BrineWater_m3_tonLCE]])
A21: 20 | B21: 1 | D21: Los Angeles | E21: Diablillios/Sal de Los Angeles | F21: 37628 | G21: Brine | H21: 0.0002 | I21: 3 | K21: 281 | L21: =+Table2[[#This Row],[Brine Water]]+Table2[[#This Row],[Freshwater]] -> 281 | M21: kg | N21: kg LCE Battery grade | O21: Yes | P21: DLE technology from continental brines | Q21: Freshwater consumption | R21: 3 | S21: =+VLOOKUP(R21,Refs[],2,0) -> Schenker & Pfister (2025) | T21: =IF(ISBLANK(Table2[[#This Row],[Brine Water]]),"",+VLOOKUP(Table2[[#This Row],[Unit num]]&"/"&Table2[[#This Row],[Unit den]],Conversion!$A$2:$B$50,2,0)*Table2[[#This Row],[Brine Water]]) | U21: =IF(ISBLANK(Table2[[#This Row],[Freshwater]]),"",+VLOOKUP(Table2[[#This Row],[Unit num]]&"/"&Table2[[#This Row],[Unit den]],Conversion!$A$2:$B$50,2,0)*Table2[[#This Row],[Freshwater]]) -> 281 | V21: =+VLOOKUP(Table2[[#This Row],[Unit num]]&"/"&Table2[[#This Row],[Unit den]],Conversion!$A$2:$B$50,2,0)*Table2[[#This Row],[Total Water]] -> 281 | W21: =IF(ISNUMBER(FIND("Brine",Table2[[#This Row],[Type]])),1/Table2[[#This Row],[Grade ore Li%]]/5.323,"") -> 939.31993 | X21: =+IF(ISBLANK(Table2[[#This Row],[Brine Water]]),"",Table2[[#This Row],[Brine_m3_tonLCE_GradeOnly]]/Table2[[#This Row],[BrineWater_m3_tonLCE]])
A22: 21 | B22: 1 | D22: Pozuelos | E22: Pozuelos-Pastos Grandes (Pluspetrol) | F22: 77807 | G22: Brine | H22: 0.0002 | I22: 3 | K22: 328 | L22: =+Table2[[#This Row],[Brine Water]]+Table2[[#This Row],[Freshwater]] -> 328 | M22: kg | N22: kg LCE Battery grade | O22: Yes | P22: DLE technology from continental brines | Q22: Freshwater consumption | R22: 3 | S22: =+VLOOKUP(R22,Refs[],2,0) -> Schenker & Pfister (2025) | T22: =IF(ISBLANK(Table2[[#This Row],[Brine Water]]),"",+VLOOKUP(Table2[[#This Row],[Unit num]]&"/"&Table2[[#This Row],[Unit den]],Conversion!$A$2:$B$50,2,0)*Table2[[#This Row],[Brine Water]]) | U22: =IF(ISBLANK(Table2[[#This Row],[Freshwater]]),"",+VLOOKUP(Table2[[#This Row],[Unit num]]&"/"&Table2[[#This Row],[Unit den]],Conversion!$A$2:$B$50,2,0)*Table2[[#This Row],[Freshwater]]) -> 328 | V22: =+VLOOKUP(Table2[[#This Row],[Unit num]]&"/"&Table2[[#This Row],[Unit den]],Conversion!$A$2:$B$50,2,0)*Table2[[#This Row],[Total Water]] -> 328 | W22: =IF(ISNUMBER(FIND("Brine",Table2[[#This Row],[Type]])),1/Table2[[#This Row],[Grade ore Li%]]/5.323,"") -> 939.31993 | X22: =+IF(ISBLANK(Table2[[#This Row],[Brine Water]]),"",Table2[[#This Row],[Brine_m3_tonLCE_GradeOnly]]/Table2[[#This Row],[BrineWater_m3_tonLCE]])
A23: 22 | B23: 1 | D23: Chaerhan | E23: #N/A | F23: 38549 | G23: Brine | H23: 0.0002 | I23: 3 | K23: 212 | L23: =+Table2[[#This Row],[Brine Water]]+Table2[[#This Row],[Freshwater]] -> 212 | M23: kg | N23: kg LCE Battery grade | O23: Yes | P23: DLE technology from continental brines | Q23: Freshwater consumption | R23: 3 | S23: =+VLOOKUP(R23,Refs[],2,0) -> Schenker & Pfister (2025) | T23: =IF(ISBLANK(Table2[[#This Row],[Brine Water]]),"",+VLOOKUP(Table2[[#This Row],[Unit num]]&"/"&Table2[[#This Row],[Unit den]],Conversion!$A$2:$B$50,2,0)*Table2[[#This Row],[Brine Water]]) | U23: =IF(ISBLANK(Table2[[#This Row],[Freshwater]]),"",+VLOOKUP(Table2[[#This Row],[Unit num]]&"/"&Table2[[#This Row],[Unit den]],Conversion!$A$2:$B$50,2,0)*Table2[[#This Row],[Freshwater]]) -> 212 | V23: =+VLOOKUP(Table2[[#This Row],[Unit num]]&"/"&Table2[[#This Row],[Unit den]],Conversion!$A$2:$B$50,2,0)*Table2[[#This Row],[Total Water]] -> 212 | W23: =IF(ISNUMBER(FIND("Brine",Table2[[#This Row],[Type]])),1/Table2[[#This Row],[Grade ore Li%]]/5.323,"") -> 939.31993 | X23: =+IF(ISBLANK(Table2[[#This Row],[Brine Water]]),"",Table2[[#This Row],[Brine_m3_tonLCE_GradeOnly]]/Table2[[#This Row],[BrineWater_m3_tonLCE]])
A24: 23 | B24: 1 | D24: Qinghai Yiliping | E24: Qaidam Basin (All Projects) | F24: 88897 | G24: Brine | H24: 0.0002 | I24: 3 | K24: 212 | L24: =+Table2[[#This Row],[Brine Water]]+Table2[[#This Row],[Freshwater]] -> 212 | M24: kg | N24: kg LCE Battery grade | O24: Yes | P24: DLE technology from continental brines | Q24: Freshwater consumption | R24: 3 | S24: =+VLOOKUP(R24,Refs[],2,0) -> Schenker & Pfister (2025) | T24: =IF(ISBLANK(Table2[[#This Row],[Brine Water]]),"",+VLOOKUP(Table2[[#This Row],[Unit num]]&"/"&Table2[[#This Row],[Unit den]],Conversion!$A$2:$B$50,2,0)*Table2[[#This Row],[Brine Water]]) | U24: =IF(ISBLANK(Table2[[#This Row],[Freshwater]]),"",+VLOOKUP(Table2[[#This Row],[Unit num]]&"/"&Table2[[#This Row],[Unit den]],Conversion!$A$2:$B$50,2,0)*Table2[[#This Row],[Freshwater]]) -> 212 | V24: =+VLOOKUP(Table2[[#This Row],[Unit num]]&"/"&Table2[[#This Row],[Unit den]],Conversion!$A$2:$B$50,2,0)*Table2[[#This Row],[Total Water]] -> 212 | W24: =IF(ISNUMBER(FIND("Brine",Table2[[#This Row],[Type]])),1/Table2[[#This Row],[Grade ore Li%]]/5.323,"") -> 939.31993 | X24: =+IF(ISBLANK(Table2[[#This Row],[Brine Water]]),"",Table2[[#This Row],[Brine_m3_tonLCE_GradeOnly]]/Table2[[#This Row],[BrineWater_m3_tonLCE]])
A25: 26 | B25: 1 | D25: Atacama | E25: Salar de Atacama (SQM) | F25: 37384 | G25: Brine | H25: 0.0019 | I25: 4 | K25: 39131 | L25: =+Table2[[#This Row],[Brine Water]]+Table2[[#This Row],[Freshwater]] -> 39131 | M25: liters | N25: ton LCE | O25: No | P25: Brine + Chemical plant | Q25: Ground+Surface water. LCA based | R25: 4 | S25: =+VLOOKUP(R25,Refs[],2,0) -> Lagos et al. (2024) | T25: =IF(ISBLANK(Table2[[#This Row],[Brine Water]]),"",+VLOOKUP(Table2[[#This Row],[Unit num]]&"/"&Table2[[#This Row],[Unit den]],Conversion!$A$2:$B$50,2,0)*Table2[[#This Row],[Brine Water]]) | U25: =IF(ISBLANK(Table2[[#This Row],[Freshwater]]),"",+VLOOKUP(Table2[[#This Row],[Unit num]]&"/"&Table2[[#This Row],[Unit den]],Conversion!$A$2:$B$50,2,0)*Table2[[#This Row],[Freshwater]]) -> 39.131 | V25: =+VLOOKUP(Table2[[#This Row],[Unit num]]&"/"&Table2[[#This Row],[Unit den]],Conversion!$A$2:$B$50,2,0)*Table2[[#This Row],[Total Water]] -> 39.131 | W25: =IF(ISNUMBER(FIND("Brine",Table2[[#This Row],[Type]])),1/Table2[[#This Row],[Grade ore Li%]]/5.323,"") -> 98.875782 | X25: =+IF(ISBLANK(Table2[[#This Row],[Brine Water]]),"",Table2[[#This Row],[Brine_m3_tonLCE_GradeOnly]]/Table2[[#This Row],[BrineWater_m3_tonLCE]])
A26: 27 | B26: 1 | D26: Qarhan | E26: Qaidam Basin (All Projects) | F26: 85124 | G26: Brine | H26: =+(0.006%+0.025%)/2 -> 0.000155 | I26: 5 | K26: 617.1 | L26: =+Table2[[#This Row],[Brine Water]]+Table2[[#This Row],[Freshwater]] -> 617.1 | M26: m3 | N26: ton LCE | O26: Yes | P26: Adsorption+Membrane | R26: 5 | S26: =+VLOOKUP(R26,Refs[],2,0) -> Feng et al. (2025) | T26: =IF(ISBLANK(Table2[[#This Row],[Brine Water]]),"",+VLOOKUP(Table2[[#This Row],[Unit num]]&"/"&Table2[[#This Row],[Unit den]],Conversion!$A$2:$B$50,2,0)*Table2[[#This Row],[Brine Water]]) | U26: =IF(ISBLANK(Table2[[#This Row],[Freshwater]]),"",+VLOOKUP(Table2[[#This Row],[Unit num]]&"/"&Table2[[#This Row],[Unit den]],Conversion!$A$2:$B$50,2,0)*Table2[[#This Row],[Freshwater]]) -> 617.1 | V26: =+VLOOKUP(Table2[[#This Row],[Unit num]]&"/"&Table2[[#This Row],[Unit den]],Conversion!$A$2:$B$50,2,0)*Table2[[#This Row],[Total Water]] -> 617.1 | W26: =IF(ISNUMBER(FIND("Brine",Table2[[#This Row],[Type]])),1/Table2[[#This Row],[Grade ore Li%]]/5.323,"") -> 1212.0257 | X26: =+IF(ISBLANK(Table2[[#This Row],[Brine Water]]),"",Table2[[#This Row],[Brine_m3_tonLCE_GradeOnly]]/Table2[[#This Row],[BrineWater_m3_tonLCE]])
A27: 28 | B27: 1 | D27: Silver Peak | E27: Silver Peak | F27: 37600 | G27: Brine | H27: =+(0.006%+0.16%)/2 -> 0.00083 | I27: 5 | K27: 496.53 | L27: =+Table2[[#This Row],[Brine Water]]+Table2[[#This Row],[Freshwater]] -> 496.53 | M27: m3 | N27: ton LCE | O27: No | P27: Precipitation | R27: 5 | S27: =+VLOOKUP(R27,Refs[],2,0) -> Feng et al. (2025) | T27: =IF(ISBLANK(Table2[[#This Row],[Brine Water]]),"",+VLOOKUP(Table2[[#This Row],[Unit num]]&"/"&Table2[[#This Row],[Unit den]],Conversion!$A$2:$B$50,2,0)*Table2[[#This Row],[Brine Water]]) | U27: =IF(ISBLANK(Table2[[#This Row],[Freshwater]]),"",+VLOOKUP(Table2[[#This Row],[Unit num]]&"/"&Table2[[#This Row],[Unit den]],Conversion!$A$2:$B$50,2,0)*Table2[[#This Row],[Freshwater]]) -> 496.53 | V27: =+VLOOKUP(Table2[[#This Row],[Unit num]]&"/"&Table2[[#This Row],[Unit den]],Conversion!$A$2:$B$50,2,0)*Table2[[#This Row],[Total Water]] -> 496.53 | W27: =IF(ISNUMBER(FIND("Brine",Table2[[#This Row],[Type]])),1/Table2[[#This Row],[Grade ore Li%]]/5.323,"") -> 226.34215 | X27: =+IF(ISBLANK(Table2[[#This Row],[Brine Water]]),"",Table2[[#This Row],[Brine_m3_tonLCE_GradeOnly]]/Table2[[#This Row],[BrineWater_m3_tonLCE]])
A28: 29 | B28: 1 | D28: Olaroz | E28: Salar de Olaroz (Allkem) | F28: 37059 | G28: Brine | H28: =+(0.006%+0.16%)/2 -> 0.00083 | I28: 5 | K28: 271.06 | L28: =+Table2[[#This Row],[Brine Water]]+Table2[[#This Row],[Freshwater]] -> 271.06 | M28: m3 | N28: ton LCE | O28: No | P28: Precipitation | R28: 5 | S28: =+VLOOKUP(R28,Refs[],2,0) -> Feng et al. (2025) | T28: =IF(ISBLANK(Table2[[#This Row],[Brine Water]]),"",+VLOOKUP(Table2[[#This Row],[Unit num]]&"/"&Table2[[#This Row],[Unit den]],Conversion!$A$2:$B$50,2,0)*Table2[[#This Row],[Brine Water]]) | U28: =IF(ISBLANK(Table2[[#This Row],[Freshwater]]),"",+VLOOKUP(Table2[[#This Row],[Unit num]]&"/"&Table2[[#This Row],[Unit den]],Conversion!$A$2:$B$50,2,0)*Table2[[#This Row],[Freshwater]]) -> 271.06 | V28: =+VLOOKUP(Table2[[#This Row],[Unit num]]&"/"&Table2[[#This Row],[Unit den]],Conversion!$A$2:$B$50,2,0)*Table2[[#This Row],[Total Water]] -> 271.06 | W28: =IF(ISNUMBER(FIND("Brine",Table2[[#This Row],[Type]])),1/Table2[[#This Row],[Grade ore Li%]]/5.323,"") -> 226.34215 | X28: =+IF(ISBLANK(Table2[[#This Row],[Brine Water]]),"",Table2[[#This Row],[Brine_m3_tonLCE_GradeOnly]]/Table2[[#This Row],[BrineWater_m3_tonLCE]])
A29: 30 | B29: 1 | D29: Cauchari-Olaroz | E29: #N/A | F29: 37624 | G29: Brine | H29: =+(0.006%+0.16%)/2 -> 0.00083 | I29: 5 | K29: 134.33 | L29: =+Table2[[#This Row],[Brine Water]]+Table2[[#This Row],[Freshwater]] -> 134.33 | M29: m3 | N29: ton LCE | O29: No | P29: Precipitation | R29: 5 | S29: =+VLOOKUP(R29,Refs[],2,0) -> Feng et al. (2025) | T29: =IF(ISBLANK(Table2[[#This Row],[Brine Water]]),"",+VLOOKUP(Table2[[#This Row],[Unit num]]&"/"&Table2[[#This Row],[Unit den]],Conversion!$A$2:$B$50,2,0)*Table2[[#This Row],[Brine Water]]) | U29: =IF(ISBLANK(Table2[[#This Row],[Freshwater]]),"",+VLOOKUP(Table2[[#This Row],[Unit num]]&"/"&Table2[[#This Row],[Unit den]],Conversion!$A$2:$B$50,2,0)*Table2[[#This Row],[Freshwater]]) -> 134.33 | V29: =+VLOOKUP(Table2[[#This Row],[Unit num]]&"/"&Table2[[#This Row],[Unit den]],Conversion!$A$2:$B$50,2,0)*Table2[[#This Row],[Total Water]] -> 134.33 | W29: =IF(ISNUMBER(FIND("Brine",Table2[[#This Row],[Type]])),1/Table2[[#This Row],[Grade ore Li%]]/5.323,"") -> 226.34215 | X29: =+IF(ISBLANK(Table2[[#This Row],[Brine Water]]),"",Table2[[#This Row],[Brine_m3_tonLCE_GradeOnly]]/Table2[[#This Row],[BrineWater_m3_tonLCE]])
A30: 31 | B30: 1 | D30: Da Qaidam | E30: Qaidam Basin (All Projects) | F30: #N/A | G30: Brine | H30: 0.00024 | I30: 5 | K30: 113.15 | L30: =+Table2[[#This Row],[Brine Water]]+Table2[[#This Row],[Freshwater]] -> 113.15 | M30: m3 | N30: ton LCE | O30: Yes | P30: Solvent extraction | R30: 5 | S30: =+VLOOKUP(R30,Refs[],2,0) -> Feng et al. (2025) | T30: =IF(ISBLANK(Table2[[#This Row],[Brine Water]]),"",+VLOOKUP(Table2[[#This Row],[Unit num]]&"/"&Table2[[#This Row],[Unit den]],Conversion!$A$2:$B$50,2,0)*Table2[[#This Row],[Brine Water]]) | U30: =IF(ISBLANK(Table2[[#This Row],[Freshwater]]),"",+VLOOKUP(Table2[[#This Row],[Unit num]]&"/"&Table2[[#This Row],[Unit den]],Conversion!$A$2:$B$50,2,0)*Table2[[#This Row],[Freshwater]]) -> 113.15 | V30: =+VLOOKUP(Table2[[#This Row],[Unit num]]&"/"&Table2[[#This Row],[Unit den]],Conversion!$A$2:$B$50,2,0)*Table2[[#This Row],[Total Water]] -> 113.15 | W30: =IF(ISNUMBER(FIND("Brine",Table2[[#This Row],[Type]])),1/Table2[[#This Row],[Grade ore Li%]]/5.323,"") -> 782.76661 | X30: =+IF(ISBLANK(Table2[[#This Row],[Brine Water]]),"",Table2[[#This Row],[Brine_m3_tonLCE_GradeOnly]]/Table2[[#This Row],[BrineWater_m3_tonLCE]])
A31: 32 | B31: 1 | D31: Hombre Muerto | E31: Salar del Hombre Muerto (POSCO) | F31: 90185 | G31: Brine | H31: 0.0006 | I31: 5 | K31: 112.12 | L31: =+Table2[[#This Row],[Brine Water]]+Table2[[#This Row],[Freshwater]] -> 112.12 | M31: m3 | N31: ton LCE | O31: Yes | P31: Adsorption+Precipitation | R31: 5 | S31: =+VLOOKUP(R31,Refs[],2,0) -> Feng et al. (2025) | T31: =IF(ISBLANK(Table2[[#This Row],[Brine Water]]),"",+VLOOKUP(Table2[[#This Row],[Unit num]]&"/"&Table2[[#This Row],[Unit den]],Conversion!$A$2:$B$50,2,0)*Table2[[#This Row],[Brine Water]]) | U31: =IF(ISBLANK(Table2[[#This Row],[Freshwater]]),"",+VLOOKUP(Table2[[#This Row],[Unit num]]&"/"&Table2[[#This Row],[Unit den]],Conversion!$A$2:$B$50,2,0)*Table2[[#This Row],[Freshwater]]) -> 112.12 | V31: =+VLOOKUP(Table2[[#This Row],[Unit num]]&"/"&Table2[[#This Row],[Unit den]],Conversion!$A$2:$B$50,2,0)*Table2[[#This Row],[Total Water]] -> 112.12 | W31: =IF(ISNUMBER(FIND("Brine",Table2[[#This Row],[Type]])),1/Table2[[#This Row],[Grade ore Li%]]/5.323,"") -> 313.10664 | X31: =+IF(ISBLANK(Table2[[#This Row],[Brine Water]]),"",Table2[[#This Row],[Brine_m3_tonLCE_GradeOnly]]/Table2[[#This Row],[BrineWater_m3_tonLCE]])
A32: 33 | B32: 1 | D32: Yiliping | E32: Qaidam Basin (All Projects) | F32: 88897 | G32: Brine | H32: 0.00015 | I32: 5 | K32: 93.63 | L32: =+Table2[[#This Row],[Brine Water]]+Table2[[#This Row],[Freshwater]] -> 93.63 | M32: m3 | N32: ton LCE | O32: Yes | P32: Membrane | R32: 5 | S32: =+VLOOKUP(R32,Refs[],2,0) -> Feng et al. (2025) | T32: =IF(ISBLANK(Table2[[#This Row],[Brine Water]]),"",+VLOOKUP(Table2[[#This Row],[Unit num]]&"/"&Table2[[#This Row],[Unit den]],Conversion!$A$2:$B$50,2,0)*Table2[[#This Row],[Brine Water]]) | U32: =IF(ISBLANK(Table2[[#This Row],[Freshwater]]),"",+VLOOKUP(Table2[[#This Row],[Unit num]]&"/"&Table2[[#This Row],[Unit den]],Conversion!$A$2:$B$50,2,0)*Table2[[#This Row],[Freshwater]]) -> 93.63 | V32: =+VLOOKUP(Table2[[#This Row],[Unit num]]&"/"&Table2[[#This Row],[Unit den]],Conversion!$A$2:$B$50,2,0)*Table2[[#This Row],[Total Water]] -> 93.63 | W32: =IF(ISNUMBER(FIND("Brine",Table2[[#This Row],[Type]])),1/Table2[[#This Row],[Grade ore Li%]]/5.323,"") -> 1252.4266 | X32: =+IF(ISBLANK(Table2[[#This Row],[Brine Water]]),"",Table2[[#This Row],[Brine_m3_tonLCE_GradeOnly]]/Table2[[#This Row],[BrineWater_m3_tonLCE]])
A33: 34 | B33: 1 | D33: Barunma Sea | E33: #N/A | F33: #N/A | G33: Brine | H33: =+(0.006%+0.025%)/2 -> 0.000155 | I33: 5 | K33: 68.37 | L33: =+Table2[[#This Row],[Brine Water]]+Table2[[#This Row],[Freshwater]] -> 68.37 | M33: m3 | N33: ton LCE | O33: Yes | P33: Adsorption+Membrane | R33: 5 | S33: =+VLOOKUP(R33,Refs[],2,0) -> Feng et al. (2025) | T33: =IF(ISBLANK(Table2[[#This Row],[Brine Water]]),"",+VLOOKUP(Table2[[#This Row],[Unit num]]&"/"&Table2[[#This Row],[Unit den]],Conversion!$A$2:$B$50,2,0)*Table2[[#This Row],[Brine Water]]) | U33: =IF(ISBLANK(Table2[[#This Row],[Freshwater]]),"",+VLOOKUP(Table2[[#This Row],[Unit num]]&"/"&Table2[[#This Row],[Unit den]],Conversion!$A$2:$B$50,2,0)*Table2[[#This Row],[Freshwater]]) -> 68.37 | V33: =+VLOOKUP(Table2[[#This Row],[Unit num]]&"/"&Table2[[#This Row],[Unit den]],Conversion!$A$2:$B$50,2,0)*Table2[[#This Row],[Total Water]] -> 68.37 | W33: =IF(ISNUMBER(FIND("Brine",Table2[[#This Row],[Type]])),1/Table2[[#This Row],[Grade ore Li%]]/5.323,"") -> 1212.0257 | X33: =+IF(ISBLANK(Table2[[#This Row],[Brine Water]]),"",Table2[[#This Row],[Brine_m3_tonLCE_GradeOnly]]/Table2[[#This Row],[BrineWater_m3_tonLCE]])
A34: 35 | B34: 1 | D34: Atacama | E34: Salar de Atacama (SQM) | F34: 37384 | G34: Brine | H34: =+(0.006%+0.16%)/2 -> 0.00083 | I34: 5 | K34: 58.04 | L34: =+Table2[[#This Row],[Brine Water]]+Table2[[#This Row],[Freshwater]] -> 58.04 | M34: m3 | N34: ton LCE | O34: No | P34: Precipitation | R34: 5 | S34: =+VLOOKUP(R34,Refs[],2,0) -> Feng et al. (2025) | T34: =IF(ISBLANK(Table2[[#This Row],[Brine Water]]),"",+VLOOKUP(Table2[[#This Row],[Unit num]]&"/"&Table2[[#This Row],[Unit den]],Conversion!$A$2:$B$50,2,0)*Table2[[#This Row],[Brine Water]]) | U34: =IF(ISBLANK(Table2[[#This Row],[Freshwater]]),"",+VLOOKUP(Table2[[#This Row],[Unit num]]&"/"&Table2[[#This Row],[Unit den]],Conversion!$A$2:$B$50,2,0)*Table2[[#This Row],[Freshwater]]) -> 58.04 | V34: =+VLOOKUP(Table2[[#This Row],[Unit num]]&"/"&Table2[[#This Row],[Unit den]],Conversion!$A$2:$B$50,2,0)*Table2[[#This Row],[Total Water]] -> 58.04 | W34: =IF(ISNUMBER(FIND("Brine",Table2[[#This Row],[Type]])),1/Table2[[#This Row],[Grade ore Li%]]/5.323,"") -> 226.34215 | X34: =+IF(ISBLANK(Table2[[#This Row],[Brine Water]]),"",Table2[[#This Row],[Brine_m3_tonLCE_GradeOnly]]/Table2[[#This Row],[BrineWater_m3_tonLCE]])
A35: 36 | B35: 1 | D35: West Tajinar | E35: #N/A | F35: 38542 | G35: Brine | H35: 0.00021 | I35: 5 | K35: 54.93 | L35: =+Table2[[#This Row],[Brine Water]]+Table2[[#This Row],[Freshwater]] -> 54.93 | M35: m3 | N35: ton LCE | O35: No | P35: Calcination | R35: 5 | S35: =+VLOOKUP(R35,Refs[],2,0) -> Feng et al. (2025) | T35: =IF(ISBLANK(Table2[[#This Row],[Brine Water]]),"",+VLOOKUP(Table2[[#This Row],[Unit num]]&"/"&Table2[[#This Row],[Unit den]],Conversion!$A$2:$B$50,2,0)*Table2[[#This Row],[Brine Water]]) | U35: =IF(ISBLANK(Table2[[#This Row],[Freshwater]]),"",+VLOOKUP(Table2[[#This Row],[Unit num]]&"/"&Table2[[#This Row],[Unit den]],Conversion!$A$2:$B$50,2,0)*Table2[[#This Row],[Freshwater]]) -> 54.93 | V35: =+VLOOKUP(Table2[[#This Row],[Unit num]]&"/"&Table2[[#This Row],[Unit den]],Conversion!$A$2:$B$50,2,0)*Table2[[#This Row],[Total Water]] -> 54.93 | W35: =IF(ISNUMBER(FIND("Brine",Table2[[#This Row],[Type]])),1/Table2[[#This Row],[Grade ore Li%]]/5.323,"") -> 894.59041 | X35: =+IF(ISBLANK(Table2[[#This Row],[Brine Water]]),"",Table2[[#This Row],[Brine_m3_tonLCE_GradeOnly]]/Table2[[#This Row],[BrineWater_m3_tonLCE]])
A36: 37 | B36: 1 | D36: East Tajinar | E36: #N/A | F36: 38543 | G36: Brine | H36: 0.00085 | I36: 5 | K36: 34.1 | L36: =+Table2[[#This Row],[Brine Water]]+Table2[[#This Row],[Freshwater]] -> 34.1 | M36: m3 | N36: ton LCE | O36: Yes | P36: Electrodialysis | R36: 5 | S36: =+VLOOKUP(R36,Refs[],2,0) -> Feng et al. (2025) | T36: =IF(ISBLANK(Table2[[#This Row],[Brine Water]]),"",+VLOOKUP(Table2[[#This Row],[Unit num]]&"/"&Table2[[#This Row],[Unit den]],Conversion!$A$2:$B$50,2,0)*Table2[[#This Row],[Brine Water]]) | U36: =IF(ISBLANK(Table2[[#This Row],[Freshwater]]),"",+VLOOKUP(Table2[[#This Row],[Unit num]]&"/"&Table2[[#This Row],[Unit den]],Conversion!$A$2:$B$50,2,0)*Table2[[#This Row],[Freshwater]]) -> 34.1 | V36: =+VLOOKUP(Table2[[#This Row],[Unit num]]&"/"&Table2[[#This Row],[Unit den]],Conversion!$A$2:$B$50,2,0)*Table2[[#This Row],[Total Water]] -> 34.1 | W36: =IF(ISNUMBER(FIND("Brine",Table2[[#This Row],[Type]])),1/Table2[[#This Row],[Grade ore Li%]]/5.323,"") -> 221.01645 | X36: =+IF(ISBLANK(Table2[[#This Row],[Brine Water]]),"",Table2[[#This Row],[Brine_m3_tonLCE_GradeOnly]]/Table2[[#This Row],[BrineWater_m3_tonLCE]])
A37: 51 | B37: 1 | D37: Olaroz | E37: Salar de Olaroz (Allkem) | F37: 37059 | G37: Brine | H37: =630/1000000 -> 0.00063 | I37: Li Article | J37: 537.4 | K37: 51 | L37: =+Table2[[#This Row],[Brine Water]]+Table2[[#This Row],[Freshwater]] -> 588.4 | M37: m3 | N37: ton LCE Battery Grade | O37: No | R37: 10 | S37: =+VLOOKUP(R37,Refs[],2,0) -> Paz et al. (2025) | T37: =IF(ISBLANK(Table2[[#This Row],[Brine Water]]),"",+VLOOKUP(Table2[[#This Row],[Unit num]]&"/"&Table2[[#This Row],[Unit den]],Conversion!$A$2:$B$50,2,0)*Table2[[#This Row],[Brine Water]]) -> 537.4 | U37: =IF(ISBLANK(Table2[[#This Row],[Freshwater]]),"",+VLOOKUP(Table2[[#This Row],[Unit num]]&"/"&Table2[[#This Row],[Unit den]],Conversion!$A$2:$B$50,2,0)*Table2[[#This Row],[Freshwater]]) -> 51 | V37: =+VLOOKUP(Table2[[#This Row],[Unit num]]&"/"&Table2[[#This Row],[Unit den]],Conversion!$A$2:$B$50,2,0)*Table2[[#This Row],[Total Water]] -> 588.4 | W37: =IF(ISNUMBER(FIND("Brine",Table2[[#This Row],[Type]])),1/Table2[[#This Row],[Grade ore Li%]]/5.323,"") -> 298.1968 | X37: =+IF(ISBLANK(Table2[[#This Row],[Brine Water]]),"",Table2[[#This Row],[Brine_m3_tonLCE_GradeOnly]]/Table2[[#This Row],[BrineWater_m3_tonLCE]]) -> 0.55488799
A38: 52 | B38: 1 | D38: Fenix | E38: Salar del Hombre Muerto (Livent) | F38: 37611 | G38: Brine | H38: =523/1000000 -> 0.000523 | I38: Li Article | J38: 319.6 | K38: 135.5 | L38: =+Table2[[#This Row],[Brine Water]]+Table2[[#This Row],[Freshwater]] -> 455.1 | M38: m3 | N38: ton LCE Battery Grade | O38: No | R38: 10 | S38: =+VLOOKUP(R38,Refs[],2,0) -> Paz et al. (2025) | T38: =IF(ISBLANK(Table2[[#This Row],[Brine Water]]),"",+VLOOKUP(Table2[[#This Row],[Unit num]]&"/"&Table2[[#This Row],[Unit den]],Conversion!$A$2:$B$50,2,0)*Table2[[#This Row],[Brine Water]]) -> 319.6 | U38: =IF(ISBLANK(Table2[[#This Row],[Freshwater]]),"",+VLOOKUP(Table2[[#This Row],[Unit num]]&"/"&Table2[[#This Row],[Unit den]],Conversion!$A$2:$B$50,2,0)*Table2[[#This Row],[Freshwater]]) -> 135.5 | V38: =+VLOOKUP(Table2[[#This Row],[Unit num]]&"/"&Table2[[#This Row],[Unit den]],Conversion!$A$2:$B$50,2,0)*Table2[[#This Row],[Total Water]] -> 455.1 | W38: =IF(ISNUMBER(FIND("Brine",Table2[[#This Row],[Type]])),1/Table2[[#This Row],[Grade ore Li%]]/5.323,"") -> 359.20456 | X38: =+IF(ISBLANK(Table2[[#This Row],[Brine Water]]),"",Table2[[#This Row],[Brine_m3_tonLCE_GradeOnly]]/Table2[[#This Row],[BrineWater_m3_tonLCE]]) -> 1.1239192
A39: 56 | B39: 1 | D39: Brine high grade | F39: #N/A | G39: Brine | H39: 0.001048 | I39: 13 | J39: 162.79 | K39: =154.1-116.28 -> 37.82 | L39: =+Table2[[#This Row],[Brine Water]]+Table2[[#This Row],[Freshwater]] -> 200.61 | M39: kg | N39: kg LCE Battery grade | O39: No | P39: Simulation based, evaporation (Atacama). Includes water emmissions to system | R39: 13 | S39: =+VLOOKUP(R39,Refs[],2,0) -> Mas-Fons et al. (2024) | T39: =IF(ISBLANK(Table2[[#This Row],[Brine Water]]),"",+VLOOKUP(Table2[[#This Row],[Unit num]]&"/"&Table2[[#This Row],[Unit den]],Conversion!$A$2:$B$50,2,0)*Table2[[#This Row],[Brine Water]]) -> 162.79 | U39: =IF(ISBLANK(Table2[[#This Row],[Freshwater]]),"",+VLOOKUP(Table2[[#This Row],[Unit num]]&"/"&Table2[[#This Row],[Unit den]],Conversion!$A$2:$B$50,2,0)*Table2[[#This Row],[Freshwater]]) -> 37.82 | V39: =+VLOOKUP(Table2[[#This Row],[Unit num]]&"/"&Table2[[#This Row],[Unit den]],Conversion!$A$2:$B$50,2,0)*Table2[[#This Row],[Total Water]] -> 200.61 | W39: =IF(ISNUMBER(FIND("Brine",Table2[[#This Row],[Type]])),1/Table2[[#This Row],[Grade ore Li%]]/5.323,"") -> 179.25953 | X39: =+IF(ISBLANK(Table2[[#This Row],[Brine Water]]),"",Table2[[#This Row],[Brine_m3_tonLCE_GradeOnly]]/Table2[[#This Row],[BrineWater_m3_tonLCE]]) -> 1.1011704
A40: 57 | B40: 1 | D40: Brine medium grade | F40: #N/A | G40: Brine | H40: 0.000347 | I40: 13 | J40: 543.7 | K40: =447.22-388.35 -> 58.87 | L40: =+Table2[[#This Row],[Brine Water]]+Table2[[#This Row],[Freshwater]] -> 602.57 | M40: kg | N40: kg LCE Battery grade | O40: No | P40: Simulation based, evaporation (Atacama). Includes water emmissions to system | R40: 13 | S40: =+VLOOKUP(R40,Refs[],2,0) -> Mas-Fons et al. (2024) | T40: =IF(ISBLANK(Table2[[#This Row],[Brine Water]]),"",+VLOOKUP(Table2[[#This Row],[Unit num]]&"/"&Table2[[#This Row],[Unit den]],Conversion!$A$2:$B$50,2,0)*Table2[[#This Row],[Brine Water]]) -> 543.7 | U40: =IF(ISBLANK(Table2[[#This Row],[Freshwater]]),"",+VLOOKUP(Table2[[#This Row],[Unit num]]&"/"&Table2[[#This Row],[Unit den]],Conversion!$A$2:$B$50,2,0)*Table2[[#This Row],[Freshwater]]) -> 58.87 | V40: =+VLOOKUP(Table2[[#This Row],[Unit num]]&"/"&Table2[[#This Row],[Unit den]],Conversion!$A$2:$B$50,2,0)*Table2[[#This Row],[Total Water]] -> 602.57 | W40: =IF(ISNUMBER(FIND("Brine",Table2[[#This Row],[Type]])),1/Table2[[#This Row],[Grade ore Li%]]/5.323,"") -> 541.39477 | X40: =+IF(ISBLANK(Table2[[#This Row],[Brine Water]]),"",Table2[[#This Row],[Brine_m3_tonLCE_GradeOnly]]/Table2[[#This Row],[BrineWater_m3_tonLCE]]) -> 0.99576011
...

Sheet Vera2023_DLE
A1: SI Table S3 | C1: Vera, M. L., Torres, W. R., Galli, C. I., Chagnes, A., & Flexer, V. (2023). Environmental impact of direct lithium extraction from brines. Nature Reviews Earth & Environment, 4(3), 149-165.
A2: Technology | B2: Freshwater requirements (m3 of water per tonne of Li2CO3) | C2: Final Li+ concentration after DLE processing (g l-1) grams/liter | D2: Reference
A3: Liquid-liquid extraction | B3: 0.06 | C3: 4.4 | D3: 74 | H3: Average values | I3: m3 per tLCE | J3: grams/Liter
A4: Liquid-liquid extraction | B4: 2591 | C4: 0.09 | D4: 75 | H4: Liquid-liquid extraction | I4: =+AVERAGE(B3:B14) -> 302.69333 | J4: =+AVERAGE(C3:C14) -> 6.4275
A5: Liquid-liquid extraction | B5: 756.5 | C5: 0.3 | D5: 76 | H5: Ion Exchange resins | I5: =+AVERAGE(B17:B33) -> 6074.6047 | J5: =+AVERAGE(C17:C33) -> 0.27226667
A6: Liquid-liquid extraction | B6: 0.81 | C6: 1.25 | D6: 85 | H6: Ion-pumping | I6: =+AVERAGE(B34:B51) -> 1019.6444 | J6: =+AVERAGE(C34:C51) -> 1.4016667
A7: Liquid-liquid extraction | B7: 29.6 | C7: 20.92 | D7: 77
A8: Liquid-liquid extraction | B8: 2.11 | C8: 1.27 | D8: 78 | H8: DLE | I8: =+AVERAGE(B3:B51) -> 2886.8942 | J8: =+AVERAGE(C3:C51) -> 2.5136923
A9: Liquid-liquid extraction | B9: 188.62 | C9: 20 | D9: 79
A10: Liquid-liquid extraction | B10: 1.99 | C10: 0.99 | D10: 80
A11: Liquid-liquid extraction | B11: 0.08 | C11: 1.18 | D11: 81
A12: Liquid-liquid extraction | B12: 1.12 | C12: 15.05 | D12: 82
A13: Liquid-liquid extraction | B13: 0.18 | C13: 8.25 | D13: 83
A14: Liquid-liquid extraction | B14: 60.25 | C14: 3.43 | D14: 86
A15: Ion Exchange resins | B15: N/R | C15: N/R | D15: 48
A16: Ion Exchange resins | B16: N/R | C16: N/R | D16: 49
A17: Ion Exchange resins | B17: 9.09 | C17: 0.62 | D17: 87
A18: Ion Exchange resins | B18: 32.88 | C18: 0.24 | D18: 88
A19: Ion Exchange resins | B19: 2684 | C19: 0.014 | D19: 89
A20: Ion Exchange resins | B20: 188 | C20: 0.05 | D20: 50
A21: Ion Exchange resins | B21: 7994 | C21: 0.005 | D21: 90
A22: Ion Exchange resins | B22: 226.2 | C22: 0.041 | D22: 91
A23: Ion Exchange resins | B23: 8.2 | C23: 0.229 | D23: 51
A24: Ion Exchange resins | B24: 462 | C24: 0.061 | D24: 52
A25: Ion Exchange resins | B25: N/R | C25: N/R | D25: 53
A26: Ion Exchange resins | B26: 60604 | C26: 0.003 | D26: 54
A27: Ion Exchange resins | B27: 18787 | C27: 0.001 | D27: 55
A28: Ion Exchange resins | B28: 20.35 | C28: 0.277 | D28: 56
A29: Ion Exchange resins | B29: 18.1 | C29: 0.347 | D29: 57
A30: Ion Exchange resins | B30: 2.74 | C30: 0.342 | D30: 58
A31: Ion Exchange resins | B31: 0.11 | C31: 1.74 | D31: 59
A32: Ion Exchange resins | B32: N/R | C32: N/R | D32: 60
A33: Ion Exchange resins | B33: 82.4 | C33: 0.114 | D33: 61
A34: Ion-pumping | B34: N/R | C34: N/R | D34: 10
A35: Ion-pumping | B35: 229.6 | C35: 0.09 | D35: 11
A36: Ion-pumping | B36: N/R | C36: 0.49 | D36: 13
A37: Ion-pumping | B37: N/R | C37: N/R | D37: 12
A38: Ion-pumping | B38: N/R | C38: N/R | D38: 14
A39: Ion-pumping | B39: 4169.3 | C39: 0.14 | D39: 92
A40: Ion-pumping | B40: 90.3 | C40: 0.21 | D40: 93
...

Sheet Conversion
A1: Comb | B1: Factor_m3/tonLCE
A2: kg/kg LCE Battery grade | B2: 1
A3: liters/ton LCE | B3: =1/1000 -> 0.001
A4: m3/ton LCE | B4: 1
A5: kg/kg LCE | B5: 1
A6: kg/kg LiOH.H2O | B6: =1/0.8808 -> 1.1353315
A7: kg/ton LCE | B7: =1/1000 -> 0.001
A8: m3/ton LCE Battery Grade | B8: 1
A9: m3/ton Li | B9: =1/5.323 -> 0.18786399
A10: ton/ton LCE | B10: 1

Sheet References
A1: ID | B1: Name | C1: Full cite | D1: Year | E1: DOI | F1: Notes | G1: Type
A2: 1 | B2: GREET
A3: 2 | B3: ecoinvent
A4: 3 | B4: Schenker & Pfister (2025) | C4: Schenker, Vanessa, and Stephan Pfister. "Current and Future Impacts of Lithium Carbonate from Brines: A Global Regionalized Life Cycle Assessment Model." Environmental Science & Technology 59.13 (2025): 6543-6555. | D4: 2025 | E4: https://doi.org/10.1021/acs.est.4c12619 | G4: Freshwater consumption
A5: 4 | B5: Lagos et al. (2024) | C5: Lagos, G., Cifuentes, L., Peters, D., Castro, L., & Valdés, J. M. (2024). Carbon footprint and water inventory of the production of lithium in the Atacama Salt Flat, Chile. Environmental Challenges, 16, 100962. | D5: 2024 | E5: https://doi.org/10.1016/j.envc.2024.100962 | G5: Water consumption
A6: 5 | B6: Feng et al. (2025) | C6: Feng, Y., Feng, D., Sun, X., Liu, Z., Li, W., & Wang, P. (2025). Environmental Impacts of Lithium Brines Across the World: Brine Quality, Technology Choices and Regional Disparities. ACS Sustainable Chemistry & Engineering, 13(38), 15828-15838. | D6: 2025 | E6: https://doi.org/10.1021/acssuschemeng.5c03739 | G6: Water consumption
A7: 6 | B7: Feng et al. (2024) | C7: Feng, Y., Wang, P., Li, W., Zhang, Q., Chen, W. Q., & Feng, D. (2024). Environmental impacts of lithium supply chains from Australia to China. Environmental Research Letters, 19(9), 094035. | D7: 2024 | E7: 10.1088/1748-9326/ad69ac | G7: Water consumption
A8: 7 | B8: Iyer & Kelly (2024) | C8: Iyer, R. K., & Kelly, J. C. (2024). Life-cycle analysis of lithium chemical production in the United States. RSC Sustainability, 2(12), 3929-3945. | D8: 2024 | E8: https://doi.org/10.1039/D4SU00446A | G8: Water consumption
A9: 8 | B9: Iyer, Kelly & Wang (2026) | C9: Iyer, R. K., Kelly, J. C., & Wang, M. (2026). Life-cycle greenhouse gas emissions analysis of battery-grade lithium production in Finland. Resources, Conservation and Recycling, 225, 108592. | D9: 2026 | E9: https://doi.org/10.1016/j.resconrec.2025.108592 | G9: Water consumption
A10: 9 | B10: Khakmardan et al. (2024) | C10: Khakmardan, S., Li, W., Giurco, D., & Crawford, R. (2024). Life cycle assessment of lithium carbonate production: Comparing sedimentary deposits. Journal of Cleaner Production, 467, 142955. | D10: 2024 | E10: https://doi.org/10.1016/j.jclepro.2024.142955 | G10: Water consumption
A11: 10 | B11: Paz et al. (2025) | C11: Paz, W. F. D., Seghezzo, L., Barboza, A. G. S., Escosteguy, M., Arias-Alvarado, P. V., Kruse, E., ... & Iribarnegaray, M. A. (2025). The water footprint of lithium extraction technologies: Insights from environmental impact reports in Argentina's salt flats. Heliyon, 11(4). | E11: https://doi.org/10.1016/j.heliyon.2025.e42523 | G11: Water consumption
A12: 11 | B12: Mousavinezhad et al. (2025) | C12: Mousavinezhad, S., Fahimi, A., Sharifian, S., & Vahidi, E. (2025). Sustainable lithium production from sedimentary rock deposits: Carbon reduction and EV synergies. Resources, Conservation and Recycling, 218, 108271. | D12: 2025 | E12: https://doi.org/10.1016/j.resconrec.2025.108271 | G12: Water consumption
A13: 12 | B13: Roy et al. (2024) | C13: Roy, V., Paranthaman, M. P., & Zhao, F. (2024). Lithium from clay: Assessing the environmental impacts of extraction. Sustainable Production and Consumption, 52, 324-332. | D13: 2024 | E13: https://doi.org/10.1016/j.spc.2024.11.008 | G13: Water consumption
A14: 13 | B14: Mas-Fons et al. (2024) | C14: Mas-Fons, A., Arduin, R. H., Loubet, P., Pereira, T., Parvez, A. M., & Sonnemann, G. (2024). Carbon and water footprint of battery-grade lithium from brine and spodumene: A simulation-based LCA. Journal of Cleaner Production, 452, 142108. | D14: 2024 | E14: https://doi.org/10.1016/j.jclepro.2024.142108 | F14: Good data on SI on LI deposit grade ore | G14: Water consumption
A15: 14 | B15: Sun et al. (2024) | C15: Sun, X., Giljum, S., Maus, V., Schomberg, A., Zhang, S., & You, F. (2025). Robust assessments of lithium mining impacts embodied in global supply chain require spatially explicit analyses. Environmental Science & Technology, 59(14), 7081-7094. | D15: 2025 | E15: 10.1021/acs.est.4c12749 | F15: Good data on SI and they use withdarwal ratio rather than AWARE (for impact characterization) | G15: Water use
A16: 15 | B16: Orquera et al. (2026) | C16: Orquera, E., Xu, G., Werner, T., Northey, S., Tiku, O., Giurco, D., & Matsubae, K. (2026). Lithium in Latin America: A dynamic material flow analysis and mapping CO2, water, and land footprints to 2050. Resources, Conservation and Recycling, 226, 108677. | D16: 2026 | E16: https://doi.org/10.1016/j.resconrec.2025.108677 | F16: They have technological progress scenario. It also has land impact. | G16: No data point used
A17: 16 | B17: Vera et al. (2023) | C17: Vera, M. L., Torres, W. R., Galli, C. I., Chagnes, A., & Flexer, V. (2023). Environmental impact of direct lithium extraction from brines. Nature Reviews Earth & Environment, 4(3), 149-165. | D17: 2023 | E17: https://doi.org/10.1038/s43017-022-00387-5 | F17: Data of 57 articles compiled on this review | G17: Freshwater consumption
A18: 17 | B18: Halkers et al. (2024) | C18: Halkes, R. T., Hughes, A., Wall, F., Petavratzi, E., Pell, R., & Lindsay, J. J. (2024). Life cycle assessment and water use impacts of lithium production from salar deposits: Challenges and opportunities. Resources, Conservation and Recycling, 207, 107554. | D18: 2024 | E18: https://doi.org/10.1016/j.resconrec.2024.107554 | G18: No data point used
